Workbook

Sheet Danh mục
A1: Phân loại | B1: Mô tả | D1: Tình trạng
A2: Chi nhánh | B2: Theo dõi hàng có BBSC chi nhánh, TBYT hư hỏng trả hãng | D2: Bán | H2: Có | J2: Chuyển bán
A3: Chi nhánh - PAP | B3: Hàng PAP Chi nhánh, phải có BBGN từ BV | D3: Hủy | H3: Không | J3: Chuyển hủy
A4: Chuyển kho | B4: Chuyển về hãng, chuyển kho thuê sang kho bán hoặc ngược lại | D4: Đơn chỉ định | J4: Đơn chỉ định
A5: Hết date tại kho | B5: Chuyển hủy theo diện hết date (chỉ mail chỗ chị như / nhóm CXL) | D5: Xuất | J5: Xuất mẫu
A6: Khác | D6: Chưa xác định | J6: Chưa xác định
A7: Sự cố hãng - Đã Approved | B7: Hãng gửi mail xác nhận hàng hoá, trước khi hàng về | D7: Trả hãng
A8: Thu hồi chuyển HỦY
A9: Trả về - Chuyển hủy
A10: Trả về - CXL | B10: Trả về có sự cố nhưng không release / chuyển CXL có thông tin từ hãng / chờ xuất về hãng theo y/c
A11: Trả về - PAP | B11: Hàng PAP trả về, phải có BBGN từ BV
A12: Trả về - Release | B12: Trả về có sự cố nhưng release
A13: Yêu cầu từ hãng | B13: Hãng yêu cầu xử lý hàng
A15: Phân loại | B15: Mô tả
A16: Đền bù vận chuyển
A17: Yêu cầu hãng | B17: Chờ trả hãng, chờ hủy, release
A18: PAP | B18: Chờ hủy,…
A19: Trả về - release | B19: Nhiệt độ vận chuyển, móp nhẹ mà mình release
A20: Planning xác nhận
A21: Nội bộ kho xử lý | B21: Kho tự xử lý, ra đơn, đền bù
A22: Yêu cầu CSKH

Sheet Theo dõi 2024-2026
A1: Ngày | B1: Số theo dõi | C1: Phân loại | D1: Mã SP/ Item | E1: TÊN SẢN PHẨM/ Product's name | F1: Batch | G1: HSD | H1: LPN | I1: SỐ LƯỢNG | J1: Nội dung | K1: Tình trạng | L1: Ghi Chú | M1: Link dẫn | N1: Hành động | O1: Tồn
A2: 45440 | B2: INT-0001-24 | C2: Nội bộ kho xử lý | D2: SA5211011 | E2: VERORAB BOX OF 10 VIALS + 10 SYRINGES | F2: W1C332V | G2: 45961 | H2: 000138900 | I2: 300 | J2: Trả về tại kho - | M2: =HYPERLINK("P:\7. LONG HAU\7. CAC THEO DOI TRONG QUA TRINH\4. DEVIATION- INCIDENTS\THEO DÕI NỘI BỘ (NGOÀI BBSC)\"&YEAR(A2)&"\"&B2,B2) -> INT-0001-24 | O2: Không
A3: 45446 | B3: INT-0002-24 | C3: Trả về | D3: SA5211005 | E3: HEXAXIM BOX OF 1 PRE-FILLED SYRINGE + 2 NEEDLES | F3: W3G601V | G3: 46142 | H3: 000139236 | I3: 1 | J3: Không có thuốc bên trong hộp | K3: Xuất | L3: CC_210324 | M3: =HYPERLINK("P:\7. LONG HAU\7. CAC THEO DOI TRONG QUA TRINH\4. DEVIATION- INCIDENTS\THEO DÕI NỘI BỘ (NGOÀI BBSC)\"&YEAR(A3)&"\"&B3,B3) -> INT-0002-24 | O3: Không
A4: 45446 | B4: INT-0003-24 | C4: Yêu cầu hãng | D4: SC6100011 | E4: PERFECTIL (H/30 VIEN) | F4: PFT2167P | G4: 45443 | H4: 000139260 | I4: 7 | J4: Cận date | K4: Chưa xác định | M4: =HYPERLINK("P:\7. LONG HAU\7. CAC THEO DOI TRONG QUA TRINH\4. DEVIATION- INCIDENTS\THEO DÕI NỘI BỘ (NGOÀI BBSC)\"&YEAR(A4)&"\"&B4,B4) -> INT-0003-24 | O4: Có
A5: 45446 | B5: INT-0003-24 | C5: Yêu cầu hãng | D5: SC6100007 | E5: JOINTACE (H/30 VIEN) | F5: 156077 | G5: 45443 | H5: 000139261 | I5: 18 | J5: Cận date | K5: Chưa xác định | M5: =HYPERLINK("P:\7. LONG HAU\7. CAC THEO DOI TRONG QUA TRINH\4. DEVIATION- INCIDENTS\THEO DÕI NỘI BỘ (NGOÀI BBSC)\"&YEAR(A5)&"\"&B5,B5) -> INT-0003-24 | O5: Có
A6: 45446 | B6: INT-0003-24 | C6: Yêu cầu hãng | D6: SC6100011 | E6: PERFECTIL (H/30 VIEN) | F6: PFT2166P | G6: 45443 | H6: 000139262 | I6: 4 | J6: Cận date | K6: Chưa xác định | M6: =HYPERLINK("P:\7. LONG HAU\7. CAC THEO DOI TRONG QUA TRINH\4. DEVIATION- INCIDENTS\THEO DÕI NỘI BỘ (NGOÀI BBSC)\"&YEAR(A6)&"\"&B6,B6) -> INT-0003-24 | O6: Có
A7: 45446 | B7: INT-0003-24 | C7: Yêu cầu hãng | D7: SC6100019 | E7: WELLBABY MULTI-VITAMIN LIQUID (CHAI 150ML) | F7: 21043 | G7: 45443 | H7: 000139264 | I7: 3 | J7: Cận date | K7: Chưa xác định | M7: =HYPERLINK("P:\7. LONG HAU\7. CAC THEO DOI TRONG QUA TRINH\4. DEVIATION- INCIDENTS\THEO DÕI NỘI BỘ (NGOÀI BBSC)\"&YEAR(A7)&"\"&B7,B7) -> INT-0003-24 | O7: Có
A8: 45446 | B8: INT-0003-24 | C8: Yêu cầu hãng | D8: SC6100002 | E8: FEROGLOBIN B12 LIQUID 200ML | F8: 21049 | G8: 45443 | H8: 000139263 | I8: 16 | J8: Cận date | K8: Chưa xác định | M8: =HYPERLINK("P:\7. LONG HAU\7. CAC THEO DOI TRONG QUA TRINH\4. DEVIATION- INCIDENTS\THEO DÕI NỘI BỘ (NGOÀI BBSC)\"&YEAR(A8)&"\"&B8,B8) -> INT-0003-24 | O8: Có
A9: 45446 | B9: INT-0003-24 | C9: Yêu cầu hãng | D9: SC6100002 | E9: FEROGLOBIN B12 LIQUID 200ML | F9: 20635 | G9: 45443 | H9: 000139267 | I9: 1 | J9: Cận date | K9: Chưa xác định | M9: =HYPERLINK("P:\7. LONG HAU\7. CAC THEO DOI TRONG QUA TRINH\4. DEVIATION- INCIDENTS\THEO DÕI NỘI BỘ (NGOÀI BBSC)\"&YEAR(A9)&"\"&B9,B9) -> INT-0003-24 | O9: Có
A10: 45446 | B10: INT-0003-24 | C10: Yêu cầu hãng | D10: SC6100007 | E10: JOINTACE (H/30 VIEN) | F10: 156077A | G10: 45443 | H10: 000139266 | I10: 25 | J10: Cận date | K10: Chưa xác định | M10: =HYPERLINK("P:\7. LONG HAU\7. CAC THEO DOI TRONG QUA TRINH\4. DEVIATION- INCIDENTS\THEO DÕI NỘI BỘ (NGOÀI BBSC)\"&YEAR(A10)&"\"&B10,B10) -> INT-0003-24 | O10: Có
A11: 45446 | B11: INT-0003-24 | C11: Yêu cầu hãng | D11: SC6100019 | E11: WELLBABY MULTI-VITAMIN LIQUID (CHAI 150ML) | F11: 21042 | G11: 45443 | H11: 000139268 | I11: 6 | J11: Cận date | K11: Chưa xác định | M11: =HYPERLINK("P:\7. LONG HAU\7. CAC THEO DOI TRONG QUA TRINH\4. DEVIATION- INCIDENTS\THEO DÕI NỘI BỘ (NGOÀI BBSC)\"&YEAR(A11)&"\"&B11,B11) -> INT-0003-24 | O11: Có
A12: 45446 | B12: INT-0003-24 | C12: Yêu cầu hãng | D12: SC6100017 | E12: WELLKID MULTI-VITAMIN LIQUID (CHAI/150ML) | F12: 21017 | G12: 45443 | H12: 000139265 | I12: 10 | J12: Cận date | K12: Chưa xác định | M12: =HYPERLINK("P:\7. LONG HAU\7. CAC THEO DOI TRONG QUA TRINH\4. DEVIATION- INCIDENTS\THEO DÕI NỘI BỘ (NGOÀI BBSC)\"&YEAR(A12)&"\"&B12,B12) -> INT-0003-24 | O12: Có
A13: 45446 | B13: INT-0003-24 | C13: Yêu cầu hãng | D13: SC6100011 | E13: PERFECTIL (H/30 VIEN) | F13: PFT21114P | G13: 45473 | H13: 000139272 | I13: 1 | J13: Cận date | K13: Chưa xác định | M13: =HYPERLINK("P:\7. LONG HAU\7. CAC THEO DOI TRONG QUA TRINH\4. DEVIATION- INCIDENTS\THEO DÕI NỘI BỘ (NGOÀI BBSC)\"&YEAR(A13)&"\"&B13,B13) -> INT-0003-24 | O13: Có
A14: 45446 | B14: INT-0003-24 | C14: Yêu cầu hãng | D14: SC6100001 | E14: OSTEOCARE LIQUID 200ML | F14: 21170 | G14: 45473 | H14: 000139273 | I14: 4 | J14: Cận date | K14: Chưa xác định | M14: =HYPERLINK("P:\7. LONG HAU\7. CAC THEO DOI TRONG QUA TRINH\4. DEVIATION- INCIDENTS\THEO DÕI NỘI BỘ (NGOÀI BBSC)\"&YEAR(A14)&"\"&B14,B14) -> INT-0003-24 | O14: Có
A15: 45446 | B15: INT-0003-24 | C15: Yêu cầu hãng | D15: SC6100001 | E15: OSTEOCARE LIQUID 200ML | F15: 21261 | G15: 45473 | H15: 000139274 | I15: 8 | J15: Cận date | K15: Chưa xác định | M15: =HYPERLINK("P:\7. LONG HAU\7. CAC THEO DOI TRONG QUA TRINH\4. DEVIATION- INCIDENTS\THEO DÕI NỘI BỘ (NGOÀI BBSC)\"&YEAR(A15)&"\"&B15,B15) -> INT-0003-24 | O15: Có
A16: 45446 | B16: INT-0003-24 | C16: Yêu cầu hãng | D16: SC6100018 | E16: PREGNACARE BREAST-FEEDING (HOP/56 VIEN NEN, 28 VIEN NANG) | F16: PB2230 | G16: 45565 | H16: 000139275 | I16: 2 | J16: Cận date | K16: Chưa xác định | L16: Đã xuất đi | M16: =HYPERLINK("P:\7. LONG HAU\7. CAC THEO DOI TRONG QUA TRINH\4. DEVIATION- INCIDENTS\THEO DÕI NỘI BỘ (NGOÀI BBSC)\"&YEAR(A16)&"\"&B16,B16) -> INT-0003-24 | O16: Không
A17: 45446 | B17: INT-0003-24 | C17: Yêu cầu hãng | D17: SC6100019 | E17: WELLBABY MULTI-VITAMIN LIQUID (CHAI 150ML) | F17: 21659 | G17: 45565 | H17: 000139269 | I17: 2 | J17: Cận date | K17: Chưa xác định | L17: Đã xuất đi | M17: =HYPERLINK("P:\7. LONG HAU\7. CAC THEO DOI TRONG QUA TRINH\4. DEVIATION- INCIDENTS\THEO DÕI NỘI BỘ (NGOÀI BBSC)\"&YEAR(A17)&"\"&B17,B17) -> INT-0003-24 | O17: Không
A18: 45446 | B18: INT-0003-24 | C18: Yêu cầu hãng | D18: SC6100017 | E18: WELLKID MULTI-VITAMIN LIQUID (CHAI/150ML) | F18: 21571 | G18: 45535 | H18: 000139270 | I18: 1 | J18: Cận date | K18: Chưa xác định | L18: Đã xuất đi | M18: =HYPERLINK("P:\7. LONG HAU\7. CAC THEO DOI TRONG QUA TRINH\4. DEVIATION- INCIDENTS\THEO DÕI NỘI BỘ (NGOÀI BBSC)\"&YEAR(A18)&"\"&B18,B18) -> INT-0003-24 | O18: Không
A19: 45446 | B19: INT-0003-24 | C19: Yêu cầu hãng | D19: SC6100015 | E19: PREGNACARE PLUS OMEGA 3 (H/56 VIEN) | F19: PP2139 | G19: 45504 | H19: 000139271 | I19: 1 | J19: Cận date | K19: Chưa xác định | L19: Đã xuất đi | M19: =HYPERLINK("P:\7. LONG HAU\7. CAC THEO DOI TRONG QUA TRINH\4. DEVIATION- INCIDENTS\THEO DÕI NỘI BỘ (NGOÀI BBSC)\"&YEAR(A19)&"\"&B19,B19) -> INT-0003-24 | O19: Có
A20: 45446 | B20: INT-0004-24 | C20: Yêu cầu hãng | D20: SA1207001 | E20: NO-SPA 40MG/2ML INJ AM25 VN | F20: GC459A | G20: 46187 | H20: 000139942 | I20: 2.92 | J20: ADR | K20: Xuất | L20: Đã xuất đi | M20: =HYPERLINK("P:\7. LONG HAU\7. CAC THEO DOI TRONG QUA TRINH\4. DEVIATION- INCIDENTS\THEO DÕI NỘI BỘ (NGOÀI BBSC)\"&YEAR(A20)&"\"&B20,B20) -> INT-0004-24 | O20: Không
A21: 45450 | B21: INT-0005-24 | C21: Yêu cầu hãng | D21: AZ1100018 | E21: KOMBOGLYZE XR 5MG/1000MG BOX OF 4 BLISTERS X 7 FILM-COATED T | F21: NP0109 | G21: 45638 | H21: 000139989 | I21: 1 | J21: Móp do vận chuyển | K21: Đơn chỉ định | L21: Đã xuất đi | M21: =HYPERLINK("P:\7. LONG HAU\7. CAC THEO DOI TRONG QUA TRINH\4. DEVIATION- INCIDENTS\THEO DÕI NỘI BỘ (NGOÀI BBSC)\"&YEAR(A21)&"\"&B21,B21) -> INT-0005-24 | O21: Không
A22: 45450 | B22: INT-0005-24 | C22: Yêu cầu hãng | D22: AZ1100019 | E22: KOMBOGLYZE XR 5MG/500MG BOX OF 4 BLISTERS X 7 FILM-COATED TA | F22: NP0205 | G22: 45660 | H22: 000139990 | I22: 1 | J22: Móp do vận chuyển | K22: Đơn chỉ định | L22: Đã xuất đi | M22: =HYPERLINK("P:\7. LONG HAU\7. CAC THEO DOI TRONG QUA TRINH\4. DEVIATION- INCIDENTS\THEO DÕI NỘI BỘ (NGOÀI BBSC)\"&YEAR(A22)&"\"&B22,B22) -> INT-0005-24 | O22: Không
A23: 45450 | B23: INT-0005-24 | C23: Yêu cầu hãng | D23: AZ1100017 | E23: ONGLYZA 5MG BOX OF 2 BLISTERS X 14 FILM-COATED TABLETS | F23: SD785 | G23: 45768 | H23: 000139988 | I23: 1 | J23: Móp do vận chuyển | K23: Đơn chỉ định | L23: Đã xuất đi | M23: =HYPERLINK("P:\7. LONG HAU\7. CAC THEO DOI TRONG QUA TRINH\4. DEVIATION- INCIDENTS\THEO DÕI NỘI BỘ (NGOÀI BBSC)\"&YEAR(A23)&"\"&B23,B23) -> INT-0005-24 | O23: Không
A24: 45450 | B24: INT-0005-24 | C24: Yêu cầu hãng | D24: AZ1100012 | E24: ONGLYZA 2.5 MG BOX OF 2 BLISTERS X 14 FILM-COATED TABLETS | F24: SA595 | G24: 45537 | H24: 000139987 | I24: 1 | J24: Móp do vận chuyển | K24: Đơn chỉ định | L24: Đã xuất đi | M24: =HYPERLINK("P:\7. LONG HAU\7. CAC THEO DOI TRONG QUA TRINH\4. DEVIATION- INCIDENTS\THEO DÕI NỘI BỘ (NGOÀI BBSC)\"&YEAR(A24)&"\"&B24,B24) -> INT-0005-24 | O24: Không
A25: 45454 | B25: INT-0006-24 | C25: Yêu cầu hãng | D25: SC6100015 | E25: PREGNACARE PLUS OMEGA 3 (H/56 VIEN) | F25: PP2212 | G25: 45565 | H25: 000140092 | I25: 9 | J25: Cận date | K25: Chưa xác định | M25: =HYPERLINK("P:\7. LONG HAU\7. CAC THEO DOI TRONG QUA TRINH\4. DEVIATION- INCIDENTS\THEO DÕI NỘI BỘ (NGOÀI BBSC)\"&YEAR(A25)&"\"&B25,B25) -> INT-0006-24 | O25: Có
A26: 45454 | B26: INT-0006-24 | C26: Yêu cầu hãng | D26: SC6100018 | E26: PREGNACARE BREAST-FEEDING (HOP/56 VIEN NEN, 28 VIEN NANG) | F26: PB2314 | G26: 45900 | H26: 000140090 | I26: 10 | J26: Cận date | K26: Chưa xác định | M26: =HYPERLINK("P:\7. LONG HAU\7. CAC THEO DOI TRONG QUA TRINH\4. DEVIATION- INCIDENTS\THEO DÕI NỘI BỘ (NGOÀI BBSC)\"&YEAR(A26)&"\"&B26,B26) -> INT-0006-24 | O26: Có
A27: 45454 | B27: INT-0006-24 | C27: Yêu cầu hãng | D27: SC6100018 | E27: PREGNACARE BREAST-FEEDING (HOP/56 VIEN NEN, 28 VIEN NANG) | F27: PB2320 | G27: 45900 | H27: 000140093 | I27: 1 | J27: Cận date | K27: Chưa xác định | M27: =HYPERLINK("P:\7. LONG HAU\7. CAC THEO DOI TRONG QUA TRINH\4. DEVIATION- INCIDENTS\THEO DÕI NỘI BỘ (NGOÀI BBSC)\"&YEAR(A27)&"\"&B27,B27) -> INT-0006-24 | O27: Có
A28: 45454 | B28: INT-0006-24 | C28: Yêu cầu hãng | D28: SC6100003 | E28: FEROGLOBIN B12 CAPSULES (H/30 VIEN) | F28: FW2201AA | G28: 45961 | H28: 000140094 | I28: 1 | J28: Cận date | K28: Chưa xác định | M28: =HYPERLINK("P:\7. LONG HAU\7. CAC THEO DOI TRONG QUA TRINH\4. DEVIATION- INCIDENTS\THEO DÕI NỘI BỘ (NGOÀI BBSC)\"&YEAR(A28)&"\"&B28,B28) -> INT-0006-24 | O28: Có
A29: 45454 | B29: INT-0007-24 | C29: Hết date tại kho | D29: AV1100012 | E29: PLENMOXI (H/1VI/10VIEN) | F29: 417BE03 | G29: 45450 | H29: 000137173 | I29: 2499 | J29: Hết date | K29: Hủy | M29: =HYPERLINK("P:\7. LONG HAU\7. CAC THEO DOI TRONG QUA TRINH\4. DEVIATION- INCIDENTS\THEO DÕI NỘI BỘ (NGOÀI BBSC)\"&YEAR(A29)&"\"&B29,B29) -> INT-0007-24 | O29: Không
A30: 45454 | B30: INT-0008-24 | C30: Yêu cầu hãng | D30: SC6100017 | E30: WELLKID MULTI-VITAMIN LIQUID (CHAI/150ML) | F30: 21571 | G30: 45535 | H30: 000140089 | I30: 3 | J30: Cận date | K30: Xuất | M30: =HYPERLINK("P:\7. LONG HAU\7. CAC THEO DOI TRONG QUA TRINH\4. DEVIATION- INCIDENTS\THEO DÕI NỘI BỘ (NGOÀI BBSC)\"&YEAR(A30)&"\"&B30,B30) -> INT-0008-24 | O30: Không
A31: 45455 | B31: INT-0009-24 | C31: Yêu cầu hãng | D31: SC6100001 | E31: OSTEOCARE LIQUID 200ML | F31: 21170 | G31: 45473 | H31: 000140252 | I31: 1 | J31: Cận date | K31: Chưa xác định | L31: Long Châu | M31: =HYPERLINK("P:\7. LONG HAU\7. CAC THEO DOI TRONG QUA TRINH\4. DEVIATION- INCIDENTS\THEO DÕI NỘI BỘ (NGOÀI BBSC)\"&YEAR(A31)&"\"&B31,B31) -> INT-0009-24 | O31: Có
A32: 45455 | B32: INT-0009-24 | C32: Yêu cầu hãng | D32: SC6100001 | E32: OSTEOCARE LIQUID 200ML | F32: 30159 | G32: 45688 | H32: 000140253 | I32: 1 | J32: Cận date | K32: Xuất | L32: Long Châu | M32: =HYPERLINK("P:\7. LONG HAU\7. CAC THEO DOI TRONG QUA TRINH\4. DEVIATION- INCIDENTS\THEO DÕI NỘI BỘ (NGOÀI BBSC)\"&YEAR(A32)&"\"&B32,B32) -> INT-0009-24 | N32: Xuất mẫu về VP VE đi ngày 30/08/2024 | O32: Không
A33: 45455 | B33: INT-0009-24 | C33: Yêu cầu hãng | D33: SC6100015 | E33: PREGNACARE PLUS OMEGA 3 (H/56 VIEN) | F33: PP2212 | G33: 45565 | H33: 000140249 | I33: 7 | J33: Cận date | K33: Xuất | L33: Long Châu | M33: =HYPERLINK("P:\7. LONG HAU\7. CAC THEO DOI TRONG QUA TRINH\4. DEVIATION- INCIDENTS\THEO DÕI NỘI BỘ (NGOÀI BBSC)\"&YEAR(A33)&"\"&B33,B33) -> INT-0009-24 | O33: Không
A34: 45455 | B34: INT-0009-24 | C34: Yêu cầu hãng | D34: SC6100015 | E34: PREGNACARE PLUS OMEGA 3 (H/56 VIEN) | F34: PP2237 | G34: 45688 | H34: 000140250 | I34: 1 | J34: Cận date | K34: Xuất | L34: Long Châu | M34: =HYPERLINK("P:\7. LONG HAU\7. CAC THEO DOI TRONG QUA TRINH\4. DEVIATION- INCIDENTS\THEO DÕI NỘI BỘ (NGOÀI BBSC)\"&YEAR(A34)&"\"&B34,B34) -> INT-0009-24 | N34: Xuất mẫu về VP VE đi ngày 30/08/2024 | O34: Không
A35: 45455 | B35: INT-0009-24 | C35: Yêu cầu hãng | D35: SC6100017 | E35: WELLKID MULTI-VITAMIN LIQUID (CHAI/150ML) | F35: 21573 | G35: 45565 | H35: 000140254 | I35: 10 | J35: Cận date | K35: Xuất | L35: Long Châu | M35: =HYPERLINK("P:\7. LONG HAU\7. CAC THEO DOI TRONG QUA TRINH\4. DEVIATION- INCIDENTS\THEO DÕI NỘI BỘ (NGOÀI BBSC)\"&YEAR(A35)&"\"&B35,B35) -> INT-0009-24 | O35: Không
A36: 45455 | B36: INT-0009-24 | C36: Yêu cầu hãng | D36: SC6100018 | E36: PREGNACARE BREAST-FEEDING (HOP/56 VIEN NEN, 28 VIEN NANG) | F36: PB2344 | G36: 46295 | H36: 000140251 | I36: 1 | J36: Cận date | K36: Chưa xác định | L36: Long Châu | M36: =HYPERLINK("P:\7. LONG HAU\7. CAC THEO DOI TRONG QUA TRINH\4. DEVIATION- INCIDENTS\THEO DÕI NỘI BỘ (NGOÀI BBSC)\"&YEAR(A36)&"\"&B36,B36) -> INT-0009-24 | O36: Có
A37: 45457 | B37: INT-0010-24 | C37: Yêu cầu hãng | D37: WO1100006 | E37: ALFA – LIPOGAMMA 600 ORAL BOX/100.S | F37: 21F112 | G37: 45457.75 | H37: 000140340 | I37: 5 | J37: Cận date | K37: Hủy | L37: Chờ huỷ | M37: =HYPERLINK("P:\7. LONG HAU\7. CAC THEO DOI TRONG QUA TRINH\4. DEVIATION- INCIDENTS\THEO DÕI NỘI BỘ (NGOÀI BBSC)\"&YEAR(A37)&"\"&B37,B37) -> INT-0010-24 | O37: Không
A38: 45308 | B38: INT-0011-24 | C38: Yêu cầu hãng | D38: WO1100006 | E38: ALFA – LIPOGAMMA 600 ORAL BOX/100.S | F38: 21F113 | G38: 45458 | H38: 000140649 | I38: 22 | J38: Cận date | K38: Hủy | L38: Chờ huỷ | M38: =HYPERLINK("P:\7. LONG HAU\7. CAC THEO DOI TRONG QUA TRINH\4. DEVIATION- INCIDENTS\THEO DÕI NỘI BỘ (NGOÀI BBSC)\"&YEAR(A38)&"\"&B38,B38) -> INT-0011-24 | O38: Không
A39: 45462 | B39: INT-0012-24 | C39: Chuyển kho | D39: DV1100092 | E39: DIVASER (HOP/100VIEN) | F39: 210978 | G39: 45426 | H39: 000128609 | I39: 96 | J39: Chuyển kho bán -> thuê, xuất về hãng | K39: Xuất | M39: =HYPERLINK("P:\7. LONG HAU\7. CAC THEO DOI TRONG QUA TRINH\4. DEVIATION- INCIDENTS\THEO DÕI NỘI BỘ (NGOÀI BBSC)\"&YEAR(A39)&"\"&B39,B39) -> INT-0012-24 | O39: Không
A40: 45462 | B40: INT-0012-24 | C40: Chuyển kho | D40: DV1100092 | E40: DIVASER (HOP/100VIEN) | F40: 210978 | G40: 45426 | H40: 000128609 | I40: 238 | J40: Chuyển kho bán -> thuê, xuất về hãng | K40: Xuất | M40: =HYPERLINK("P:\7. LONG HAU\7. CAC THEO DOI TRONG QUA TRINH\4. DEVIATION- INCIDENTS\THEO DÕI NỘI BỘ (NGOÀI BBSC)\"&YEAR(A40)&"\"&B40,B40) -> INT-0012-24 | O40: Không
...

Sheet Sheet1
A2: 1 | B2: Kho Long Hậu | C2: 25032025 | D2: 28888 | E2: AZ1112001 | F2: CALQUENCE PA CAP 100MG BL 10X6 EA VN | G2: ABFF | H2: 46466 | I2: CN CONG TY TNHH DUOC PHAM & TTBYT HOANG DUC | J2: D.vụ bảo quản | K2: Đã kiểm
A3: 2 | B3: Kho Long Hậu | C3: 25032025 | D3: 28888 | E3: AZ1112005 | F3: TAGRISSO PA TAB 80MG BL 3X10 EA VN | G3: FLTB | H3: 46426 | I3: CN CONG TY TNHH DUOC PHAM & TTBYT HOANG DUC | J3: D.vụ bảo quản | K3: Đã kiểm
A4: 3 | B4: Kho Long Hậu | C4: 25032025 | D4: 28888 | E4: AZ1100006 | F4: LYNPARZA 150 MG7 BLISTERS X 8 FILM-COATED TABLETS | G4: SK052 | H4: 46347 | I4: CN CONG TY TNHH DUOC PHAM & TTBYT HOANG DUC | J4: D.vụ bảo quản | K4: Đã kiểm
G12: HOANGDUC | H12: DV1100225 | I12: TEGRUCIL-1 (HOP/100VIEN) - EU | J12: 241600 | K12: 01/07/27 | L12: 000183597 | M12: 20.000 | N12: RAD | O12: HOLD | P12: VD-27453-17 | Q12: 51-359493
G13: HOANGDUC | H13: DV1100225 | I13: TEGRUCIL-1 (HOP/100VIEN) - EU | J13: 241600 | K13: 01/07/27 | L13: 000183598 | M13: 5.000 | N13: RAD | O13: HOLD | P13: VD-27453-17 | Q13: 51-359493
G14: HOANGDUC | H14: DV1100225 | I14: TEGRUCIL-1 (HOP/100VIEN) - EU | J14: 241600 | K14: 01/07/27 | L14: 000183636 | M14: 5.240 | N14: RAD | O14: HOLD | P14: VD-27453-17 | Q14: 51-359549
G15: HOANGDUC | H15: DV1100225 | I15: TEGRUCIL-1 (HOP/100VIEN) - EU | J15: 241600 | K15: 01/07/27 | L15: 000183637 | M15: 1.000 | N15: RAD | O15: HOLD | P15: VD-27453-17 | Q15: 51-359549
G21: HOANGDUC | H21: SC6100004 | I21: OSTEOCARE (H/30 VIEN) | J21: OT2201P | K21: 46053 | L21: 193070 | M21: 56 | N21: RAD | O21: HOLD | P21: 0 | Q21: 8615/2019/ĐKSP | R21: 51-384058
G22: HOANGDUC | H22: SC6100004 | I22: OSTEOCARE (H/30 VIEN) | J22: OT2203P | K22: 46053 | L22: 193071 | M22: 16 | N22: RAD | O22: HOLD | P22: 0 | Q22: 8615/2019/ĐKSP | R22: 51-384063
G23: HOANGDUC | H23: SC6100004 | I23: OSTEOCARE (H/30 VIEN) | J23: OT2204P | K23: 46053 | L23: 193072 | M23: 54 | N23: RAD | O23: HOLD | P23: 0 | Q23: 8615/2019/ĐKSP | R23: 51-384064
G24: HOANGDUC | H24: SC6100015 | I24: PREGNACARE PLUS OMEGA 3 (H/56 VIEN) | J24: PP2324 | K24: 46053 | L24: 193073 | M24: 17 | N24: RAD | O24: HOLD | P24: 0 | Q24: 9184/2019/ĐKSP | R24: 51-384066
F28: M00106 | G28: SC6100007 | H28: JOINTACE (H/30 VIEN) | I28: 162793 | J28: 45930 | K28: 201690 | L28: 29 | M28: STAGE | N28: HOLD | O28: 0 | P28: 10281/2019/ĐKSP | Q28: 33049
F29: M00106 | G29: SC6100007 | H29: JOINTACE (H/30 VIEN) | I29: 163763 | J29: 46022 | K29: 201689 | L29: 2 | M29: STAGE | N29: HOLD | O29: 0 | P29: 10281/2019/ĐKSP | Q29: 33049
