Workbook

Sheet Danh mục
A1: \\hd.domain\hoangducdfs\TAILIEUPHONG-HD\P.QA\7. LONG HAU\7. CAC THEO DOI TRONG QUA TRINH\18. FORM MAU CHO FOLDER NHA SAN XUAT\ | B1: \5. THONG TIN NHAP - PHAN PHOI\1. KIEM NHAP\ | E1: check | F1: 5. THONG TIN NHAP - PHAN PHOI | G1: 1. KIEM NHAP | H1: NAM 2024
A2: ABBOTT | D2: Hyphens | E2: =HYPERLINK('Danh mục'!$A$1&D2,D2) -> Hyphens
A3: ADAMED PHARMA | D3: WOERWAG | E3: =HYPERLINK('Danh mục'!$A$1&D3,D3) -> WOERWAG
A4: AJ | D4: Besin | E4: =HYPERLINK('Danh mục'!$A$1&D4,D4) -> Besin
A5: ALLEVIARE - GLENMARK | D5: PARADIGM | E5: =HYPERLINK('Danh mục'!$A$1&D5,D5) -> PARADIGM
A6: AMVI | D6: OEP - ORIENT | E6: =HYPERLINK('Danh mục'!$A$1&D6,D6) -> OEP - ORIENT
A7: ANIOS | D7: Hetero | E7: =HYPERLINK('Danh mục'!$A$1&D7,D7) -> Hetero
A8: APPASAMY | D8: VITABIOTICS - VE | E8: =HYPERLINK('Danh mục'!$A$1&D8,D8) -> VITABIOTICS - VE
A9: ASCENSIA | D9: Getz | E9: =HYPERLINK('Danh mục'!$A$1&D9,D9) -> Getz
A10: ASSOCT PHARMA | D10: Danone | E10: =HYPERLINK('Danh mục'!$A$1&D10,D10) -> Danone
A11: ASTRAZENECA | D11: DR.REDDY | E11: =HYPERLINK('Danh mục'!$A$1&D11,D11) -> DR.REDDY
A12: BABE | D12: HOE | E12: =HYPERLINK('Danh mục'!$A$1&D12,D12) -> HOE
A13: BESIN | D13: Abbott | E13: =HYPERLINK('Danh mục'!$A$1&D13,D13) -> Abbott
... A24: DR.WOLF | D24: UPJOHN EXPORT B.V | E24: =HYPERLINK('Danh mục'!$A$1&D24,D24) -> UPJOHN EXPORT B.V
A25: DVBQ
A26: EISAI
A27: EURO VILLAGE
A28: GETZ
A29: GetzBros
A30: GLOMED
A31: GONSA
A32: HEMOSTASIS
A33: HETERO
A34: HOE
A35: HYPHENS
A36: j&J
... A77: UPJOHN EXPORT B.V

Sheet Nhập khẩu
A1: 30/01/00 | B1: INV No. | C1: Hãng | D1: Sản phẩm | E1: Nhập Kho Long Hậu | F1: Nhập Kho Hà Nội | G1: COA | H1: Nhãn phụ | I1: Vấn đề | J1: Tiến độ | K1: Ghi chú | L1: Link INV | M1: Link hãng | N1: DATA LOGGER | O1: Số lượng | P1: DATA out of range
A2: 45376 | B2: INUK-240025 | C2: LUYE | D2: SEROQUEL XR 50MG 200MG 300MG | E2: 45428 | G2: Đã cập nhật | H2: DNNK&PP | J2: Hoàn tất | L2: =HYPERLINK('Danh mục'!$A$1&C2&'Danh mục'!$B$1&"NAM "&YEAR(A2)&"\"&SUBSTITUTE(B2,"/","-"),B2) -> INUK-240025 | M2: =HYPERLINK('Danh mục'!$A$1&C2&'Danh mục'!$B$1&"NAM "&YEAR(A2),C2) -> LUYE | N2: Không
A3: 45390 | B3: SI 24-000237 | C3: Hyphens | D3: Dorithricin | F3: 45393 | G3: Đã cập nhật | H3: Nhãn phụ SP | I3: 1. COA: Sai khác khoảng chấp nhận của phần ĐL. 2. HSD (COA) là giữa tháng khác với HSD (hộp) là cuối tháng - do trên hộp định dạng mm/yyyy | J3: Hoàn tất | K3: 1. Khoảng chấp nhận của phần ĐL đã điều chỉnh lại thành %, đúng với spec 2. HSD trên COA hãng điều chỉnh lại cuối tháng (chỉ áp dụng 1 lô này) | L3: =HYPERLINK('Danh mục'!$A$1&C3&'Danh mục'!$B$1&"NAM "&YEAR(A3)&"\"&SUBSTITUTE(B3,"/","-"),B3) -> SI 24-000237 | M3: =HYPERLINK('Danh mục'!$A$1&C3&'Danh mục'!$B$1&"NAM "&YEAR(A3),C3) -> Hyphens
A4: 45390 | B4: SI 24-000238 | C4: Hyphens | D4: PIASCLEDINE | F4: 45397 | G4: Đã cập nhật | H4: DNNK&PP | J4: Hoàn tất | L4: =HYPERLINK('Danh mục'!$A$1&C4&'Danh mục'!$B$1&"NAM "&YEAR(A4)&"\"&SUBSTITUTE(B4,"/","-"),B4) -> SI 24-000238 | M4: =HYPERLINK('Danh mục'!$A$1&C4&'Danh mục'!$B$1&"NAM "&YEAR(A4),C4) -> Hyphens | N4: PDF Temp.
A5: 45390 | B5: SI 24-000240 | C5: Hyphens | D5: PIASCLEDINE | E5: 45397 | G5: Đã cập nhật | H5: DNNK&PP | J5: Hoàn tất | L5: =HYPERLINK('Danh mục'!$A$1&C5&'Danh mục'!$B$1&"NAM "&YEAR(A5)&"\"&SUBSTITUTE(B5,"/","-"),B5) -> SI 24-000240 | M5: =HYPERLINK('Danh mục'!$A$1&C5&'Danh mục'!$B$1&"NAM "&YEAR(A5),C5) -> Hyphens | N5: PDF Temp. | O5: 1 | P5: OK
A6: 45391 | B6: 91696554 | C6: WOERWAG | D6: Ferrola | E6: 45404 | G6: Đã cập nhật | H6: DNNK&PP | J6: Hoàn tất | L6: =HYPERLINK('Danh mục'!$A$1&C6&'Danh mục'!$B$1&"NAM "&YEAR(A6)&"\"&SUBSTITUTE(B6,"/","-"),B6) -> 91696554 | M6: =HYPERLINK('Danh mục'!$A$1&C6&'Danh mục'!$B$1&"NAM "&YEAR(A6),C6) -> WOERWAG | N6: TempTale | O6: 4 | P6: OK
A7: 45392 | B7: SI 24-000247 | C7: Hyphens | D7: STERIMAR NOSE HYGIENE BABY 50 ML | F7: 45414 | G7: Đã cập nhật | H7: Nhãn phụ SP | J7: Hoàn tất | L7: =HYPERLINK('Danh mục'!$A$1&C7&'Danh mục'!$B$1&"NAM "&YEAR(A7)&"\"&SUBSTITUTE(B7,"/","-"),B7) -> SI 24-000247 | M7: =HYPERLINK('Danh mục'!$A$1&C7&'Danh mục'!$B$1&"NAM "&YEAR(A7),C7) -> Hyphens
A8: 45392 | B8: SD1-8101C-2404-00006 | C8: Besin | D8: UTROGESTAN 200 MG | E8: 45419 | G8: Đã cập nhật | H8: Nhãn phụ SP | J8: Hoàn tất | L8: =HYPERLINK('Danh mục'!$A$1&C8&'Danh mục'!$B$1&"NAM "&YEAR(A8)&"\"&SUBSTITUTE(B8,"/","-"),B8) -> SD1-8101C-2404-00006 | M8: =HYPERLINK('Danh mục'!$A$1&C8&'Danh mục'!$B$1&"NAM "&YEAR(A8),C8) -> Besin | N8: TempMate | O8: 2 | P8: max 30.5
A9: 45394 | B9: 91697444 | C9: WOERWAG | D9: Alfa Lipogamma 600 Oral | E9: 45408 | G9: Đã cập nhật | H9: DNNK&PP | J9: Hoàn tất | L9: =HYPERLINK('Danh mục'!$A$1&C9&'Danh mục'!$B$1&"NAM "&YEAR(A9)&"\"&SUBSTITUTE(B9,"/","-"),B9) -> 91697444 | M9: =HYPERLINK('Danh mục'!$A$1&C9&'Danh mục'!$B$1&"NAM "&YEAR(A9),C9) -> WOERWAG | N9: TempTale | O9: 21 | P9: OK
A10: 45394 | B10: SI 24-000257 | C10: Hyphens | D10: Dorithricin | F10: 45440 | G10: Đã cập nhật | H10: Nhãn phụ SP | I10: 1. COA: Sai khác khoảng chấp nhận của phần ĐL. 2. HSD (COA) là giữa tháng khác với HSD (hộp) là cuối tháng - do trên hộp định dạng mm/yyyy | J10: Hoàn tất | K10: 1. Khoảng chấp nhận của phần ĐL đã điều chỉnh lại thành %, đúng với spec 2. BS thông tin trên nhãn phụ 13/05/24: Hãng gửi lại COA điều chỉnh lại HSD cuối tháng | L10: =HYPERLINK('Danh mục'!$A$1&C10&'Danh mục'!$B$1&"NAM "&YEAR(A10)&"\"&SUBSTITUTE(B10,"/","-"),B10) -> SI 24-000257 | M10: =HYPERLINK('Danh mục'!$A$1&C10&'Danh mục'!$B$1&"NAM "&YEAR(A10),C10) -> Hyphens
A11: 45397 | B11: SI 24-000259 | C11: Hyphens | D11: LIPIODOL | E11: 45399 | G11: Đã cập nhật | H11: Nhãn phụ SP | J11: Hoàn tất | L11: =HYPERLINK('Danh mục'!$A$1&C11&'Danh mục'!$B$1&"NAM "&YEAR(A11)&"\"&SUBSTITUTE(B11,"/","-"),B11) -> SI 24-000259 | M11: =HYPERLINK('Danh mục'!$A$1&C11&'Danh mục'!$B$1&"NAM "&YEAR(A11),C11) -> Hyphens | N11: TempSen | O11: 3 | P11: max 46.0
A12: 45398 | B12: 17/2024 | C12: PARADIGM | D12: FLEMING | E12: 45420 | G12: Đã cập nhật | H12: Không | I12: 17/04/24: Speci nsx không khớp COA | J12: Hoàn tất | K12: Hãng không chịu gửi spec. Nhưng hàng này mình đã nhập nhiều lần. COA hiện tại giống COA cũ | L12: =HYPERLINK('Danh mục'!$A$1&C12&'Danh mục'!$B$1&"NAM "&YEAR(A12)&"\"&SUBSTITUTE(B12,"/","-"),B12) -> 17/2024 | M12: =HYPERLINK('Danh mục'!$A$1&C12&'Danh mục'!$B$1&"NAM "&YEAR(A12),C12) -> PARADIGM | N12: Không
A13: 45399 | B13: SI3623229138 | C13: Hetero | D13: Etoricoxib Tablets 60mg | E13: 45399 | G13: Đã cập nhật | H13: DNNK&PP | J13: Hoàn tất | L13: =HYPERLINK('Danh mục'!$A$1&C13&'Danh mục'!$B$1&"NAM "&YEAR(A13)&"\"&SUBSTITUTE(B13,"/","-"),B13) -> SI3623229138 | M13: =HYPERLINK('Danh mục'!$A$1&C13&'Danh mục'!$B$1&"NAM "&YEAR(A13),C13) -> Hetero | N13: Không
A14: 45399 | B14: 20240319 | C14: OEP - ORIENT | D14: Pitator Tablets 2mg | E14: 45406 | G14: Đã cập nhật | H14: Không | J14: Hoàn tất | L14: =HYPERLINK('Danh mục'!$A$1&C14&'Danh mục'!$B$1&"NAM "&YEAR(A14)&"\"&SUBSTITUTE(B14,"/","-"),B14) -> 20240319 | M14: =HYPERLINK('Danh mục'!$A$1&C14&'Danh mục'!$B$1&"NAM "&YEAR(A14),C14) -> OEP - ORIENT | N14: Không
A15: 45401 | B15: SI 24-000249 | C15: Hyphens | D15: STERIMAR NOSE HYGIENE BABY 50 ML | F15: 45418 | G15: Đã cập nhật | H15: Nhãn phụ SP | J15: Hoàn tất | L15: =HYPERLINK('Danh mục'!$A$1&C15&'Danh mục'!$B$1&"NAM "&YEAR(A15)&"\"&SUBSTITUTE(B15,"/","-"),B15) -> SI 24-000249 | M15: =HYPERLINK('Danh mục'!$A$1&C15&'Danh mục'!$B$1&"NAM "&YEAR(A15),C15) -> Hyphens
A16: 45404 | B16: SI9224200239 | C16: Hetero | D16: APIXTRA | E16: 45408 | G16: Đã cập nhật | H16: Không | J16: Hoàn tất | K16: Hàng về lần đầu | L16: =HYPERLINK('Danh mục'!$A$1&C16&'Danh mục'!$B$1&"NAM "&YEAR(A16)&"\"&SUBSTITUTE(B16,"/","-"),B16) -> SI9224200239 | M16: =HYPERLINK('Danh mục'!$A$1&C16&'Danh mục'!$B$1&"NAM "&YEAR(A16),C16) -> Hetero | N16: Không
A17: 45404 | B17: VEVN/01/04/09 | C17: VITABIOTICS - VE | D17: PREGNACARE BREAST-FEEDING WELLKID MULTI-VITAMIN SMART CHEWABLE FEROGLOBIN FIZZ | E17: Đã nhập kho | G17: Đã cập nhật | H17: Nhãn phụ SP | J17: Hoàn tất | L17: =HYPERLINK('Danh mục'!$A$1&C17&'Danh mục'!$B$1&"NAM "&YEAR(A17)&"\"&SUBSTITUTE(B17,"/","-"),B17) -> VEVN/01/04/09 | M17: =HYPERLINK('Danh mục'!$A$1&C17&'Danh mục'!$B$1&"NAM "&YEAR(A17),C17) -> VITABIOTICS - VE | N17: Không
A18: 45405 | B18: GETZ/ VIET/166/2024 | C18: Getz | D18: ATASART H TAB ATASART TAB 16MG CO-TRUPRIL FENOGETZ CAPS 200MG FORTRAGET INHALER GETSITALIP TAB 100MG GETSITALIP TAB 50MG GETZGLIM TAB 4MG LIPIGET 10MG LIPIGET 20MG MEBEVER MR 200MG PROMTO TAB 20MG RICHSTATIN TAB 10MG VILGET TAB 50MG XALGETZ 0.4MG | E18: 45418 | G18: Đã cập nhật | H18: Không | I18: 06/05/24: Về kho Promto dán nhãn phụ TCCL | J18: Hoàn tất | L18: =HYPERLINK('Danh mục'!$A$1&C18&'Danh mục'!$B$1&"NAM "&YEAR(A18)&"\"&SUBSTITUTE(B18,"/","-"),B18) -> GETZ/ VIET/166/2024 | M18: =HYPERLINK('Danh mục'!$A$1&C18&'Danh mục'!$B$1&"NAM "&YEAR(A18),C18) -> Getz | N18: Không
A19: 45405 | B19: GETZ/ VIET/160/2024 | C19: Getz | D19: DIAMISU 70/30 INJECTION | F19: 45421 | G19: Đã cập nhật | H19: Không | J19: Hoàn tất | L19: =HYPERLINK('Danh mục'!$A$1&C19&'Danh mục'!$B$1&"NAM "&YEAR(A19)&"\"&SUBSTITUTE(B19,"/","-"),B19) -> GETZ/ VIET/160/2024 | M19: =HYPERLINK('Danh mục'!$A$1&C19&'Danh mục'!$B$1&"NAM "&YEAR(A19),C19) -> Getz | N19: SE345
A20: 45405 | B20: VEVN/01/04/12 | C20: VITABIOTICS - VE | D20: FEROGLOBIN B12 CAPSULES OSTEOCARE LIQUID WELLKID MULTI-VITAMIN LIQUID | E20: Đã nhập kho | G20: Đã cập nhật | H20: Nhãn phụ SP | J20: Hoàn tất | L20: =HYPERLINK('Danh mục'!$A$1&C20&'Danh mục'!$B$1&"NAM "&YEAR(A20)&"\"&SUBSTITUTE(B20,"/","-"),B20) -> VEVN/01/04/12 | M20: =HYPERLINK('Danh mục'!$A$1&C20&'Danh mục'!$B$1&"NAM "&YEAR(A20),C20) -> VITABIOTICS - VE | N20: Không
A21: 45406 | B21: SD1-8101B-2405-00101 Progestogel ve lan dau | C21: Besin | D21: Progestogel | E21: 45503 | G21: Đã cập nhật | H21: Nhãn phụ SP | I21: 24/04/24: chưa có MA, specification nsx, artwork 15/05/24: hãng gửi MA, Artwork chờ Nhãn phụ, Speci COA ko phù hợp (sai tên, thiếu địa chỉ nsx) 20/06/24: COA tên sp không khớp MA, đã báo hãng 01/07/24: đã gửi nhãn ký duyệt (chưa có vị trí dán) 10/07/2024 nhận COA đã edit nhưng đang chờ hãng gửi spec. 11/07/2024 : hãng phản hồi không có spec cho việc kiểm tra. đã lưu email từ hãng về việc confirm này | K21: Hàng về lần đầu. Hàng k có spec. nộp DAV để check mail lần đầu: INV SD1-8101B-2404-00037 | L21: =HYPERLINK('Danh mục'!$A$1&C21&'Danh mục'!$B$1&"NAM "&YEAR(A21)&"\"&SUBSTITUTE(B21,"/","-"),B21) -> SD1-8101B-2405-00101 Progestogel ve lan dau | M21: =HYPERLINK('Danh mục'!$A$1&C21&'Danh mục'!$B$1&"NAM "&YEAR(A21),C21) -> Besin | N21: Không
A22: 45406 | B22: SI-24-000298 SI-24-000299 | C22: Hyphens | D22: STERIMAR NOSE HYGIENE & COMFORT STERIMAR BLOCKED NOSE BABY STERIMAR NOSE HYGIENE BABY | F22: 45432 | G22: Đã cập nhật | H22: Nhãn phụ SP | J22: Hoàn tất | L22: =HYPERLINK('Danh mục'!$A$1&C22&'Danh mục'!$B$1&"NAM "&YEAR(A22)&"\"&SUBSTITUTE(B22,"/","-"),B22) -> SI-24-000298 SI-24-000299 | M22: =HYPERLINK('Danh mục'!$A$1&C22&'Danh mục'!$B$1&"NAM "&YEAR(A22),C22) -> Hyphens
A23: 45407 | B23: SI 24-000292 | C23: Hyphens | D23: XENETIX 300 ( VIAL 100ML) | E23: 45429 | G23: Đã cập nhật | H23: Nhãn phụ SP | J23: Hoàn tất | L23: =HYPERLINK('Danh mục'!$A$1&C23&'Danh mục'!$B$1&"NAM "&YEAR(A23)&"\"&SUBSTITUTE(B23,"/","-"),B23) -> SI 24-000292 | M23: =HYPERLINK('Danh mục'!$A$1&C23&'Danh mục'!$B$1&"NAM "&YEAR(A23),C23) -> Hyphens | N23: TempSen | O23: 9 | P23: max 25.5
A24: 45408 | B24: 8030444191 | C24: Danone | D24: FORTIMEL PROTEIN HƯƠNG DÂU FORTIMEL PROTEIN VANILLA | E24: 45421 | G24: Đã cập nhật | H24: Nhãn phụ SP | J24: Hoàn tất | L24: =HYPERLINK('Danh mục'!$A$1&C24&'Danh mục'!$B$1&"NAM "&YEAR(A24)&"\"&SUBSTITUTE(B24,"/","-"),B24) -> 8030444191 | M24: =HYPERLINK('Danh mục'!$A$1&C24&'Danh mục'!$B$1&"NAM "&YEAR(A24),C24) -> Danone | N24: Không
A25: 45651 | B25: 9013481604 | C25: DR.REDDY | D25: ZANTOLRED | E25: 45659 | G25: Đã cập nhật | H25: DNNK&PP | L25: =HYPERLINK('Danh mục'!$A$1&C25&'Danh mục'!$B$1&"NAM "&YEAR(A25)&"\"&SUBSTITUTE(B25,"/","-"),B25) -> 9013481604 | M25: =HYPERLINK('Danh mục'!$A$1&C25&'Danh mục'!$B$1&"NAM "&YEAR(A25),C25) -> DR.REDDY | N25: TempMate | O25: 2 | P25: max 28.6
A26: 45833 | B26: 9013500601 | C26: DR.REDDY | D26: ZANTOLRED | E26: 45839 | G26: Đã cập nhật | H26: DNNK | I26: Đã có CV thay đổi hạn dùng lên 36 tháng- tháng 09/2025 sẽ thay đổi snag HD mới | L26: =HYPERLINK('Danh mục'!$A$1&C26&'Danh mục'!$B$1&"NAM "&YEAR(A26)&"\"&SUBSTITUTE(B26,"/","-"),B26) -> 9013500601 | M26: =HYPERLINK('Danh mục'!$A$1&C26&'Danh mục'!$B$1&"NAM "&YEAR(A26),C26) -> DR.REDDY | N26: TempMate | O26: 2 | P26: OK
A27: 45940 | B27: 9013512637 | C27: DR.REDDY | D27: Xorafred 200mg | E27: 45959 | G27: Đã cập nhật | H27: Nhãn phụ SP | I27: Tên trên COA khác với tên trên MA, thiếu số phiếu kiểm nghiệm=> Chờ chỉnh COA=> Số phiếu kiểm nghiệm nhà máy ko bổ sung, khi nào có challenge từ Hải quan , C Hậu sẽ báo với nhà máy Hàng lần đầu về kho=> Nhãn phụ ko có mục Quy cách đóng gói=> Hãng sẽ cập nhât, khi nào có chấp nhận từ DAV mới nâng ver nhan phụ. SAU NGÀY 14/08/25 HÀNG PHẢI VỀ VỚI HẠN DÙNG 36 THÁNG | L27: =HYPERLINK('Danh mục'!$A$1&C27&'Danh mục'!$B$1&"NAM "&YEAR(A27)&"\"&SUBSTITUTE(B27,"/","-"),B27) -> 9013512637 | M27: =HYPERLINK('Danh mục'!$A$1&C27&'Danh mục'!$B$1&"NAM "&YEAR(A27),C27) -> DR.REDDY | N27: TempMate | O27: 2 | P27: OK
A28: 45502 | B28: 9013464810 | C28: DR.REDDY | D28: Winduza | E28: 45505 | G28: Đã cập nhật | H28: Nhãn phụ SP | J28: Hoàn tất | K28: Hàng về với số VISA mới trên bao bì | L28: =HYPERLINK('Danh mục'!$A$1&C28&'Danh mục'!$B$1&"NAM "&YEAR(A28)&"\"&SUBSTITUTE(B28,"/","-"),B28) -> 9013464810 | M28: =HYPERLINK('Danh mục'!$A$1&C28&'Danh mục'!$B$1&"NAM "&YEAR(A28),C28) -> DR.REDDY | N28: TempTale | O28: 1 | P28: max 33.6
A29: 45601 | B29: 9013475318 | C29: DR.REDDY | D29: Winduza | E29: 45604 | G29: Đã cập nhật | H29: Nhãn phụ SP | I29: COA KL chưa có "BATCH", nhưng đã thông quan | J29: Hoàn tất | L29: =HYPERLINK('Danh mục'!$A$1&C29&'Danh mục'!$B$1&"NAM "&YEAR(A29)&"\"&SUBSTITUTE(B29,"/","-"),B29) -> 9013475318 | M29: =HYPERLINK('Danh mục'!$A$1&C29&'Danh mục'!$B$1&"NAM "&YEAR(A29),C29) -> DR.REDDY | N29: TempTale | O29: 1 | P29: OK
A30: 45418 | B30: 21603 | C30: HOE | D30: ELLGY PLUS CRACKED HEEL CREAM | E30: 45429 | G30: Đã cập nhật | H30: Nhãn phụ SP | J30: Hoàn tất | L30: =HYPERLINK('Danh mục'!$A$1&C30&'Danh mục'!$B$1&"NAM "&YEAR(A30)&"\"&SUBSTITUTE(B30,"/","-"),B30) -> 21603 | M30: =HYPERLINK('Danh mục'!$A$1&C30&'Danh mục'!$B$1&"NAM "&YEAR(A30),C30) -> HOE | N30: Không
A31: 45418 | B31: 21602 | C31: HOE | D31: HOEBEPROSALIC OINTMENT | E31: 45436 | G31: Đã cập nhật | H31: Nhãn phụ SP | I31: 07/05/24: - Cần bổ sung Specification và CV thay đổi được duyệt - COA sai tên so với MA - AW mới, được cục duyệt. - Bao bì thực tế đã được điều chỉnh chưa? Cần hãng xác nhận - Không mail in nhãn phụ hiệu lực, chờ hàng về thực tế, do lần trước có nhiều vấn đề ở SP này | J31: Hoàn tất | K31: 11/05/24: chị Xuân xác nhận release 15/05/24: Hãng gửi lại COA | L31: =HYPERLINK('Danh mục'!$A$1&C31&'Danh mục'!$B$1&"NAM "&YEAR(A31)&"\"&SUBSTITUTE(B31,"/","-"),B31) -> 21602 | M31: =HYPERLINK('Danh mục'!$A$1&C31&'Danh mục'!$B$1&"NAM "&YEAR(A31),C31) -> HOE | N31: Không
A32: 45418 | B32: SI-24-000309 | C32: Hyphens | D32: Ocuvite Lutein | F32: 45421 | G32: Đã cập nhật | H32: Nhãn phụ SP | J32: Hoàn tất | L32: =HYPERLINK('Danh mục'!$A$1&C32&'Danh mục'!$B$1&"NAM "&YEAR(A32)&"\"&SUBSTITUTE(B32,"/","-"),B32) -> SI-24-000309 | M32: =HYPERLINK('Danh mục'!$A$1&C32&'Danh mục'!$B$1&"NAM "&YEAR(A32),C32) -> Hyphens
A33: 45418 | B33: VEVN/01/04/21 | C33: VITABIOTICS - VE | D33: OSTEOCARE CHEWABLE FEROGLOBIN B12 LIQUID | E33: Đã nhập kho | G33: Đã cập nhật | H33: Nhãn phụ SP | J33: Hoàn tất | K33: OSTEOCARE CHEWABLE về lần đầu | L33: =HYPERLINK('Danh mục'!$A$1&C33&'Danh mục'!$B$1&"NAM "&YEAR(A33)&"\"&SUBSTITUTE(B33,"/","-"),B33) -> VEVN/01/04/21 | M33: =HYPERLINK('Danh mục'!$A$1&C33&'Danh mục'!$B$1&"NAM "&YEAR(A33),C33) -> VITABIOTICS - VE | N33: Không
A34: 45740 | B34: 9013490992 | C34: DR.REDDY | D34: Winduza | E34: 45749 | G34: Đã cập nhật | H34: Nhãn phụ SP | L34: =HYPERLINK('Danh mục'!$A$1&C34&'Danh mục'!$B$1&"NAM "&YEAR(A34)&"\"&SUBSTITUTE(B34,"/","-"),B34) -> 9013490992 | M34: =HYPERLINK('Danh mục'!$A$1&C34&'Danh mục'!$B$1&"NAM "&YEAR(A34),C34) -> DR.REDDY | N34: TempTale | O34: 1 | P34: OK
A35: 45419 | B35: SI9224200460 | C35: Hetero | D35: LEVIN-500 | E35: 45421 | G35: Đã cập nhật | H35: DNNK&PP | J35: Hoàn tất | K35: Hàng về lần đầu | L35: =HYPERLINK('Danh mục'!$A$1&C35&'Danh mục'!$B$1&"NAM "&YEAR(A35)&"\"&SUBSTITUTE(B35,"/","-"),B35) -> SI9224200460 | M35: =HYPERLINK('Danh mục'!$A$1&C35&'Danh mục'!$B$1&"NAM "&YEAR(A35),C35) -> Hetero | N35: Không
A36: 45420 | B36: SD1-8101B-2405-00068, 69 | C36: Besin | D36: PAPILOCARE 2, PAPILOCARE 7 | E36: 45435 | G36: Đã cập nhật | H36: Nhãn phụ SP | I36: Chấp nhận release Nhãn phụ có số lô thêm LOT | J36: Hoàn tất | K36: Hàng về lần đầu Chị Lan chấp nhận dư "LOT",đã mail yêu cầu điều chỉnh trong đợt sau | L36: =HYPERLINK('Danh mục'!$A$1&C36&'Danh mục'!$B$1&"NAM "&YEAR(A36)&"\"&SUBSTITUTE(B36,"/","-"),B36) -> SD1-8101B-2405-00068, 69 | M36: =HYPERLINK('Danh mục'!$A$1&C36&'Danh mục'!$B$1&"NAM "&YEAR(A36),C36) -> Besin | N36: TempMate | O36: 1 | P36: max 37.4
A37: 45421 | B37: SI-24-000302 SI-24-000303 | C37: Hyphens | D37: Acne E-rase 20ml Post Peel Neutralizer 1L "C" Scape+ Serum 30ml Quick Recovery Cream 15g Ultra Light Hydrator 50g | E37: 45429 | G37: Đã cập nhật | H37: Nhãn phụ SP | J37: Hoàn tất | K37: 10/05/24: Post Peel Neutralizer 1L nhãn phụ theo số lô hd | L37: =HYPERLINK('Danh mục'!$A$1&C37&'Danh mục'!$B$1&"NAM "&YEAR(A37)&"\"&SUBSTITUTE(B37,"/","-"),B37) -> SI-24-000302 SI-24-000303 | M37: =HYPERLINK('Danh mục'!$A$1&C37&'Danh mục'!$B$1&"NAM "&YEAR(A37),C37) -> Hyphens | N37: Không
A38: 45421 | B38: SI-24-000317 | C38: Hyphens | D38: CETRAXAL | E38: 45440 | G38: Đã cập nhật | H38: Nhãn phụ SP | I38: 10/05/24: COA (thiếu tiêu chuẩn) giống COA lô trước | J38: Hoàn tất | L38: =HYPERLINK('Danh mục'!$A$1&C38&'Danh mục'!$B$1&"NAM "&YEAR(A38)&"\"&SUBSTITUTE(B38,"/","-"),B38) -> SI-24-000317 | M38: =HYPERLINK('Danh mục'!$A$1&C38&'Danh mục'!$B$1&"NAM "&YEAR(A38),C38) -> Hyphens | N38: TempTale | O38: 1 | P38: OK
A39: 45421 | B39: SI-24-000314 | C39: Hyphens | D39: Liposic Eye Gel | F39: 45432 | G39: Đã cập nhật | H39: Nhãn phụ SP | J39: Hoàn tất | L39: =HYPERLINK('Danh mục'!$A$1&C39&'Danh mục'!$B$1&"NAM "&YEAR(A39)&"\"&SUBSTITUTE(B39,"/","-"),B39) -> SI-24-000314 | M39: =HYPERLINK('Danh mục'!$A$1&C39&'Danh mục'!$B$1&"NAM "&YEAR(A39),C39) -> Hyphens
A40: 45421 | B40: SI9224200745 | C40: Hetero | D40: MONTE-H10 | E40: 45435 | G40: Đã cập nhật | H40: DNNK&PP | I40: 10/05/24: COA (Total impurities không khớp Speci nsx) giống COA lô trước | J40: Hoàn tất | K40: 17/06/24: a Khôi đã nhắn hãng gửi xác nhận thay đổi | L40: =HYPERLINK('Danh mục'!$A$1&C40&'Danh mục'!$B$1&"NAM "&YEAR(A40)&"\"&SUBSTITUTE(B40,"/","-"),B40) -> SI9224200745 | M40: =HYPERLINK('Danh mục'!$A$1&C40&'Danh mục'!$B$1&"NAM "&YEAR(A40),C40) -> Hetero | N40: Không
...

Sheet Tên COA
A1: INV | B1: SP | C1: Lot | D1: COA | E1: Check | F1: Note
A2: GETZ-VIET-522-2024 | B2: ALENTA TAB 10MG | C2: 113T23 | D2: ="COA - "&B2&" - "&C2 -> COA - ALENTA TAB 10MG - 113T23 | E2: x
A3: GETZ-VIET-522-2024 | B3: ALENTA TAB 70MG | C3: 181T24 | D3: ="COA - "&B3&" - "&C3 -> COA - ALENTA TAB 70MG - 181T24 | E3: x
A4: GETZ-VIET-522-2024 | B4: ALENTA TAB 70MG | C4: 183T24 | D4: ="COA - "&B4&" - "&C4 -> COA - ALENTA TAB 70MG - 183T24 | E4: x
A5: GETZ-VIET-522-2024 | B5: ATASART H TAB 16MG+12.5MG | C5: 228T03 | D5: ="COA - "&B5&" - "&C5 -> COA - ATASART H TAB 16MG+12.5MG - 228T03 | E5: x
A6: GETZ-VIET-522-2024 | B6: ATASART TAB 16MG | C6: 284T02 | D6: ="COA - "&B6&" - "&C6 -> COA - ATASART TAB 16MG - 284T02 | E6: x
A7: GETZ-VIET-522-2024 | B7: ATASART TAB 16MG | C7: 287T02 | D7: ="COA - "&B7&" - "&C7 -> COA - ATASART TAB 16MG - 287T02 | E7: x
A8: GETZ-VIET-522-2024 | B8: ATASART TAB 8MG | C8: 284T01 | D8: ="COA - "&B8&" - "&C8 -> COA - ATASART TAB 8MG - 284T01 | E8: x
A9: GETZ-VIET-522-2024 | B9: CELCOXX CAPS 200MG | C9: 419C02 | D9: ="COA - "&B9&" - "&C9 -> COA - CELCOXX CAPS 200MG - 419C02 | E9: x
A10: GETZ-VIET-522-2024 | B10: FENOGETZ CAPS 200MG | C10: 314C24 | D10: ="COA - "&B10&" - "&C10 -> COA - FENOGETZ CAPS 200MG - 314C24 | E10: x
A11: GETZ-VIET-522-2024 | B11: GETZGLIM TAB 4MG | C11: 462T13 | D11: ="COA - "&B11&" - "&C11 -> COA - GETZGLIM TAB 4MG - 462T13 | E11: x
A12: GETZ-VIET-522-2024 | B12: GETZLOX TAB 750MG | C12: 187F45 | D12: ="COA - "&B12&" - "&C12 -> COA - GETZLOX TAB 750MG - 187F45 | E12: x
A13: GETZ-VIET-522-2024 | B13: LIPIGET TAB 20MG | C13: 379F11 | D13: ="COA - "&B13&" - "&C13 -> COA - LIPIGET TAB 20MG - 379F11 | E13: x
... A28: GETZ-VIET-521-2024 | B28: VILGET 50MG | C28: 216T74 | D28: ="COA - "&B28&" - "&C28 -> COA - VILGET 50MG - 216T74 | E28: x
A29: 91719103 | B29: Silygamma 150mg | C29: 416318 | D29: ="COA - "&B29&" - "&C29 -> COA - Silygamma 150mg - 416318 | E29: x
A30: 91719103 | B30: Silygamma 150mg | C30: 428591 | D30: ="COA - "&B30&" - "&C30 -> COA - Silygamma 150mg - 428591 | E30: x
A31: 91719103 | B31: Silygamma 150mg | C31: 428593 | D31: ="COA - "&B31&" - "&C31 -> COA - Silygamma 150mg - 428593 | E31: x
A32: 91719103 | B32: Ferrola 50 | C32: XG0181 | D32: ="COA - "&B32&" - "&C32 -> COA - Ferrola 50 - XG0181 | E32: x
A33: 91719111 | B33: Silygamma 150mg | C33: 428581 | D33: ="COA - "&B33&" - "&C33 -> COA - Silygamma 150mg - 428581 | E33: x
A34: 91719111 | B34: Silygamma 150mg | C34: 428583 | D34: ="COA - "&B34&" - "&C34 -> COA - Silygamma 150mg - 428583 | E34: x
A35: 91719111 | B35: Silygamma 150mg | C35: 428584 | D35: ="COA - "&B35&" - "&C35 -> COA - Silygamma 150mg - 428584 | E35: x
A36: 91719111 | B36: Silygamma 150mg | C36: 428590 | D36: ="COA - "&B36&" - "&C36 -> COA - Silygamma 150mg - 428590 | E36: x
A37: 91719218 | B37: Silygamma 150mg | C37: 430343 | D37: ="COA - "&B37&" - "&C37 -> COA - Silygamma 150mg - 430343 | E37: x
A38: 91719218 | B38: Silygamma 150mg | C38: 430344 | D38: ="COA - "&B38&" - "&C38 -> COA - Silygamma 150mg - 430344 | E38: x
A39: 91719218 | B39: Silygamma 150mg | C39: 432780 | D39: ="COA - "&B39&" - "&C39 -> COA - Silygamma 150mg - 432780 | E39: x
A40: 91719218 | B40: Silygamma 150mg | C40: 432781 | D40: ="COA - "&B40&" - "&C40 -> COA - Silygamma 150mg - 432781 | E40: x
A41: GETZ/VIET/540/2024 | B41: XALGETZ 0.4MG CAPS | C41: 393C30 | D41: ="COA - "&B41&" - "&C41 -> COA - XALGETZ 0.4MG CAPS - 393C30 | E41: x
A42: GETZ/VIET/540/2024 | B42: MIRGY 100MG CAPS | C42: 373C07 | D42: ="COA - "&B42&" - "&C42 -> COA - MIRGY 100MG CAPS - 373C07 | E42: x
A43: GETZ/VIET/540/2024 | B43: ALENTA TAB 70MG | C43: 184T24 | D43: ="COA - "&B43&" - "&C43 -> COA - ALENTA TAB 70MG - 184T24 | E43: x
A44: GETZ/VIET/540/2024 | B44: MEBEVER MR 200MG | C44: 207C31 | D44: ="COA - "&B44&" - "&C44 -> COA - MEBEVER MR 200MG - 207C31 | E44: x
A45: SI 24-000717 | B45: DOTAREM 10 ML | C45: 24GD062B01 | D45: ="COA - "&B45&" - "&C45 -> COA - DOTAREM 10 ML - 24GD062B01 | E45: x
A46: SI 24-000717 | B46: DOTAREM 10 ML | C46: 24GD062A01 | D46: ="COA - "&B46&" - "&C46 -> COA - DOTAREM 10 ML - 24GD062A01 | E46: x
A47: SI 24-000721 | B47: XENETIX 300 (HOP/25 LO x 50ML) | C47: 24WC028C03 | D47: =SUBSTITUTE("COA - "&B47&" - "&C47,"/","-") -> COA - XENETIX 300 (HOP-25 LO x 50ML) - 24WC028C03 | E47: x | F47: 46478
A48: SI 24-000721 | B48: XENETIX 300 (HOP/25 LO x 50ML) | C48: 24WC037A01 | D48: =SUBSTITUTE("COA - "&B48&" - "&C48,"/","-") -> COA - XENETIX 300 (HOP-25 LO x 50ML) - 24WC037A01 | E48: x | F48: 46508
A49: SI 24-000721 | B49: XENETIX 300 (HOP/25 LO x 50ML) | C49: 24WC032A01 | D49: =SUBSTITUTE("COA - "&B49&" - "&C49,"/","-") -> COA - XENETIX 300 (HOP-25 LO x 50ML) - 24WC032A01 | E49: x | F49: 46508
A50: SI 24-000722 | B50: XENETIX 300 (HOP/10 LO x 100ML) | C50: 24WC034C01 | D50: =SUBSTITUTE("COA - "&B50&" - "&C50,"/","-") -> COA - XENETIX 300 (HOP-10 LO x 100ML) - 24WC034C01 | E50: x | F50: 46508
A51: SI 24-000722 | B51: XENETIX 300 (HOP/10 LO x 100ML) | C51: 24WC038A01 | D51: =SUBSTITUTE("COA - "&B51&" - "&C51,"/","-") -> COA - XENETIX 300 (HOP-10 LO x 100ML) - 24WC038A01 | E51: x | F51: 46539
A52: SI 24-000723 | B52: XENETIX 350 (HOP/10 LO x 100ML) | C52: 24WF062C01 | D52: =SUBSTITUTE("COA - "&B52&" - "&C52,"/","-") -> COA - XENETIX 350 (HOP-10 LO x 100ML) - 24WF062C01 | E52: x | F52: 46539
A53: SI 24-000728 | B53: XENETIX 350 (HOP/10 LO x 100ML) | C53: 24WF062C01 | D53: =SUBSTITUTE("COA - "&B53&" - "&C53,"/","-") -> COA - XENETIX 350 (HOP-10 LO x 100ML) - 24WF062C01 | E53: x | F53: 46539
A54: SI 24-000728 | B54: XENETIX 350 (HOP/10 LO x 100ML) | C54: 24WF063A01 | D54: =SUBSTITUTE("COA - "&B54&" - "&C54,"/","-") -> COA - XENETIX 350 (HOP-10 LO x 100ML) - 24WF063A01 | E54: x | F54: 46539
...

Sheet LOGGER
A1: Nhập Kho Long Hậu | B1: (All)
A3: Hãng | B3: Sản phẩm | C3: DATA LOGGER | D3: Count of INV No. | G3: DATA LOGGER
A4: Abbott | B4: 9-ASD 9-GW 9-PDA 9-PDA2 9-PDAP 9-ATV 9-ITV 9-TVLP | C4: Không | D4: 1 | G4: Elitech
A5: Abbott | B5: Amplatzer PDA2, ITV, ATV, SB, ASD, PDA, GW, PDAP, TVLP | C5: Không | D5: 1 | G5: Frigga
A6: Abbott | B6: TTBYT | C6: Không | D6: 3 | G6: PDF Temp. DATA
A7: Abbott | B7: AMPLATZER SEPTAL OCCLUDER - 9-ASD- AMPLATZER GUIDEWIRE– 9-GW AMPLATZER TREVISIO INTRAVASCULAR DELIVERY SYSTEM-ATV AMPLATZER SIZING BALLOON II AMPLATZER MUSCULAR VSD OCCLUDER-9-VSD-MUSC | C7: Không | D7: 1 | G7: SE345
A8: Abbott | B8: Amplatzer PDA 9-PDA Amplatzer ADOII 9-PDA2 Amplatzer Piccolo Occluder 9-PDAP Delivery System ITV 9-ITV Delivery System TVLP 9-TVLP | C8: Không | D8: 1 | G8: TempMate
A9: Abbott | B9: Amplatzer PDA-9PDA Delivery System ITV-9ITV (180) | C9: Không | D9: 1 | G9: TempSen
A10: Abbott | B10: Amplatzer Cribriform-9-ASD-MF Amplatzer Septal Occ-9-ASD (CR) Amplatzer Sizing Balloon II-9-SB Delivery System ITV-9ITV (180) Delivery System TVLP-9-TVLP | C10: (blank) | D10: 1 | G10: TempTale
A11: Abbott | B11: Delivery System TVLP-9-TVLP ATV07F4580 Trevisio ZFIN APZ-9 ATV Amplatzer Sizing Balloon II-9-SB Guidewire -9 GW Amplatzer ADOII- 9-PDA2 Amplatzer Piccolo Occluder-9PDAP Delivery System ITV-9ITV (180) Amplatzer PDA-9PDA Amplatzer Septal Occ-9-ASD (CR) | C11: Không | D11: 1 | G11: Weblogger TSS
A12: Abbott | B12: 9-ASD 9-PDA 9-ITV06F180/80 9-SB-018 9-TVLP4F90/080 9-TVLPC4 9 ATV 9 PDA2 9 PDAP 9 GW | C12: Không | D12: 1
A13: Abbott | B13: 9-ASD (CR) 9-PDA (US) 9-PDA2 (US) 9-GW (IE) 9-ITV 180 (US) 9-SB (US) 9-TVLP (US) 9-ATV (US) | C13: Không | D13: 1
A14: Abbott | B14: 9-PDA2 (US) 9-GW(IE) | C14: Không | D14: 1
A15: Abbott | B15: 9-ITV 180(US) | C15: Không | D15: 1
A16: Abbott | B16: 9-ITV 180 9-SB 9-TVLP 9-TVLPC 9-ATV 9-PDA 9-PDA2 9-GW (IE) 9-PDAP 9-ASD (CROATIA) | C16: Không | D16: 1
A17: ALLEVIARE - GLENMARK | B17: ACARWIN 15G | C17: Không | D17: 1
A18: ALLEVIARE - GLENMARK | B18: ARIP TABLET 10MG | C18: Không | D18: 1
A19: ALLEVIARE - GLENMARK | B19: ESOJAY | C19: Không | D19: 2
A20: ALLEVIARE - GLENMARK | B20: Esojay+ Allsilver | C20: Không | D20: 1
A21: ALLEVIARE - GLENMARK | B21: Telma 80 H Plus | C21: Không | D21: 1
A22: ALLEVIARE - GLENMARK | B22: T-Esom 40 | C22: Không | D22: 1
A23: ALLEVIARE - GLENMARK | B23: Esojay (A527) Allucot-N(A514) | C23: Không | D23: 1
... A463: TORRENT | B463: SERENATA 100 TORPEZIL 10 TORMITA 25 TORMITA 50 CELETOR TOROLAN 10 Olanzapine OD TABLETS 5mg | C463: (blank) | D463: 1
