Workbook

Sheet 2024
D1: BIỂU MẪU 02/ FORM 02 DANH SÁCH KHIẾU NẠI KHÁCH HÀNG NĂM 2024 LIST OF CUSTOMER COMPLAINTS - YEAR 2024
A3: STT No. | B3: Ngày date | C3: Code CC- | D3: Tên khách hàng Customer | E3: Địa chỉ address | F3: Tên sản phẩm Product name | G3: Số Lô batch No. | H3: NSX Mfg date | I3: HD Exp date | J3: Đơn vị tính Unit | K3: Số Lượng Quanity | L3: Lý do khiếu nại Reason of complaint | M3: Tình trạng status | N3: Xuất mẫu sang văn phòng hãng | O3: Tình trạng | P3: NCC | Q3: Yêu cầu điều tra
A4: 1 | B4: 45295 | C4: CC_010124 | D4: CHI NHANH HA NOI-CONG TY CO PHAN DUOC PHAM FPT LONG CHAU | E4: TO DAN PHO 4, THI TRAN QUANG MINH, HUYEN ME LINH, HA NOI | F4: PLENDIL PLUS 5/50 MG PROLONGED-RELEASE TABLET BOTTLE 30'S | G4: MANS | H4: NA | I4: 45584 | J4: Hộp | K4: 1 | L4: Vỏ ngoài hộp thuốc có lô MANS date 19/10/2024 Bên trong hộp thuốc lại có lô MANC hạn là 16/11/2023 (HẾT HẠN) | M4: - Do hàng mua từ CÔNG TY TNHH THƯƠNG MẠI VÀ DP SANG nên Plan sẽ gửi thông tin cho CÔNG TY TNHH THƯƠNG MẠI VÀ DP SANG về complaint này - Nhận được phản hồi từ nhà sản xuất ngày 25/01/2024--> Lỗi không từ nhà sản xuất - Tiến hành đổi trả cho khách -->Hoàn tất | N4: þ | O4: x
A5: 2 | B5: 45296 | C5: CC_020124 | D5: BENH VIEN TAM THAN | E5: 766 VO VAN KIET, P1, QUAN 5, TP. HCM | F5: DEPAKINE CHRONO 500MG TUBE OF 30 TABS VN | G5: EA3158 | H5: NA | I5: 46174 | J5: Hộp | K5: 1 | L5: Hộp bị nứt, thuốc bị dính nhau (có đính kèm hình ảnh, video) | M5: - Đã báo hãng - Nhận được hướng xử lý ngày 08/01/2024 - Ngày 15/01/2024, hàng khiếu nại về kho -->Hoàn tất | O5: x
A6: 3 | B6: 45301 | C6: CC_030124 HUY | D6: BENH VIEN VUNG TAU | E6: SO 27, DUONG 2/9 PHUONG 11, THANH PHO VUNG TAU, TINH BA RIA VUNG TAU | F6: LANTUS SOLOSTAR 100IU/ML B/5 PENS X 3ML | G6: 3F8891A | H6: NA | I6: 46053 | J6: Bút | K6: 1 | L6: Một bút Lantus Solostar không tiêm được | M6: - Đã báo hãng - Hãng không chấp nhận khiếu nại do kim novofine 31g 6mm không nằm trong danh sách kim tiêm tương thích với Lantus Solostar - Ngày 16/01/2024, sau khi trao đổi, thu mẫu của khách gửi nhà máy điều tra, sau khi có kết quả điều tra từ nhà máy mới tiến hành đền bù với khách Nhận được hướng xử lý ngày 11/01/2024 --> Hủy khiếu nại do khách không thể cung cấp chứng từ theo yêu cầu --> Hoàn tất | N6: þ | O6: x
A7: 4 | B7: 45300 | C7: CC_040124-HN | D7: CONG TY CO PHAN DAU TU DICH VU Y TE THE MEDCARE – CN HAI PHONG | E7: TẦNG 3-4 TÒA NHÀ DUY KHÁNH, SỐ 2 LÔ 22, PHƯỜNG ĐÔNG KHÊ, QUẬN NGÔ QUYỀN, HẢI PHÒNG | F7: BRUFEN SUSPENSION 60ML | G7: 53246XP | H7: NA | I7: 46169 | J7: Hộp | K7: 19 | L7: Sản phẩm bị lỗi bung nắp | M7: - khiếu nại lặp lại xử lý như CC_641123 | N7: þ | O7: x
A8: 5 | B8: 45303 | C8: CC_050124 | D8: HO KINH DOANH CHERRY SHOP | E8: DUONG CHU VAN AN, THON HIEP HOA, XA TAN HAI, THI XA LA GI, TINH BINH THUAN | F8: FONTACTIV® COMPLETE (VANILLA 800G) | G8: 3062-146 | H8: NA | I8: 45963 | J8: Lon | K8: 2 | L8: Sản phẩm bị móp trong thùng nguyên | M8: - Báo Plan complaint hãng - Nhận được hướng xuất mẫu cho hãng ngày 16/01/2024 Ngày 22/01/2024 hàng khiếu nại về kho -->Hoàn tất | N8: þ | O8: x
A9: 6 | B9: 45303 | C9: CC_060124 | D9: PHONG KHAM DA KHOA VICTORIA - CONG TY TNHH DUOC PHAM ATIPHARM | E9: 20 -20 BIS - 22 DINH TIEN HOANG, PHUONG DA KAO, QUAN 1, THANH PHO HO CHI MINH | F9: BRUFEN SUSPENSION 60ML | G9: 53246XP | H9: NA | I9: 46169 | J9: Hộp | K9: 34 | L9: Sản phẩm bị lỗi bung nắp | M9: Gửi trả hãng như các khiếu nại trước --->Hoàn tất | N9: þ | O9: x
A10: 7 | B10: 45309 | C10: CC_070124-HN | D10: BENH VIEN K TAN TRIEU | E10: 30 Đ. CẦU BƯƠU, TÂN TRIỀU, THANH TRÌ, HÀ NỘI | F10: ERANFU | G10: K230144 | H10: NA | I10: 45658 | J10: Hộp | K10: 1 | L10: Lỗi không có kim tiêm | M10: - Hàng được điều chuyển về kho LH để hủy | O10: x
A11: 8 | B11: 45321 | C11: CC_080124 | D11: NHA THUOC TAY THANG | E11: 129 NGUYEN TRAI, DIEN KHANH, KHANH HOA | F11: BRUFEN SUSPENSION 60ML | G11: 53246XP | H11: NA | I11: 46169 | J11: Hộp | K11: 3 | L11: Sản phẩm bị lỗi bung nắp | M11: Gửi trả hãng như các khiếu nại trước --->Hoàn tất | N11: þ | O11: x
A12: 9 | B12: 45323 | C12: CC_090224 | D12: KHACH HANG VANG LAI-HCM | E12: 12 NGUYEN HIEN, P4, QUAN 3, TP.HCM | F12: C SCAPE+ SERUM 30ML | G12: WG0208 | H12: NA | I12: 45991 | J12: Hộp | K12: 1 | L12: Tình trạng không đóng nắp chai kỹ, bị rò rỉ dung dịch ướt cả bên trong hộp | M12: -Gửi hãng thông tin - Chấp nhận đổi hàng cho khách - Hướng xử lý và đền bù hãng sẽ thông báo sau. Chi phí đền bù ban đầu sẽ charge vào chi phí công ty --->Hoàn tất | O12: x
A13: 10 | B13: 45327 | C13: CC_100224 | D13: NHA THUOC PHONG KHAM DA KHOA MINH HAI | E13: 214 LY THUONG KIET, KHOM 3, PHUONG 6, THANH PHO CA MAU, TINH CA MAU | F13: BRUFEN SUSPENSION 60ML | G13: 53247XP | H13: NA | I13: 46171 | J13: Hộp | K13: 3 | L13: Khi mở hộp khui ra thì nắp bị nứt | M13: Gửi trả hãng như các khiếu nại trước --->Hoàn tất | N13: þ | O13: x
A14: 11 | B14: 45341 | C14: CC_110224 | D14: PHONG TIEM CHUNG TANIMED | E14: SO 73, DUONG 30/04, PHUONG 3, TP. TAY NINH, TINH TAY NINH | F14: MENACTRA BOX OF 1 VIAL | G14: U7771BC | H14: NA | I14: 45535 | J14: Hộp | K14: 1 | L14: Không có thuốc | M14: -Gửi hãng thông tin - Ngày 19/02/2024, hãng chấp nhận khiếu nại 22/04 mẫu về kho | N14: þ | O14: x
A15: 12 | B15: 45341 | C15: CC_120224 | D15: BENH VIEN TAM THAN | E15: 766 VO VAN KIET, P1, QUAN 5, TP. HCM | F15: DEPAKINE CHRONO 500MG TUBE OF 30 TABS VN | G15: EA3159 | H15: 07/2023 | I15: 46174 | J15: Hộp | K15: 1 | L15: Trong hộp có 1 viên bị nứt đôi, chỉ phát hiện nửa viên, không phát hiện nửa viên còn lại | M15: -Gửi hãng thông tin - Nhận được hướng xử lý 20/02/2024 - Ngày 29/02/2024, hàng khiếu nại về kho, phát hiện số lô lọ và số lô trên hộp không khớp với nhau. Lý do khách báo nhầm lô. Báo email cho hãng cập nhật thông tin --->Hoàn tất | O15: x
A16: 13 | B16: 45341 | C16: CC_130224-HUY | D16: CHI NHANH CONG TY CO PHAN BENH VIEN DA KHOA TAM ANH TP. HO CHI MINH - KHOA DUOC (BVTP) | E16: 2B PHO QUANG, PHUONG 2, QUAN TAN BINH, TP. HO CHI MINH, VIET NAM | F16: TOUJEO SOLOSTAR 450IU B/5 PENS X 1.5ML | G16: 3F599A | H16: NA | I16: 45777 | J16: Bút | K16: 1 | L16: Sử dụng bút tiêm Toujeo Solostar với liều 18UI/ngày, dùng kim tiêm Novofine 6 mm, sau khi tiêm thì thấy máu xuất hiện trong uống chứa thuốc, lắc thì máu tan ra hết | M16: -Gửi hãng thông tin ngày 19/02/2024 - Hãng chấp nhận khiếu nại 03/04/2024: Hủy khiếu nại do khách đồng ý thu hồi mẫu, và cũng không yêu cầu đổi hàng --->Hoàn tất | N16: þ | O16: x
A17: 14 | B17: 45348 | C17: CC_140224 | D17: BENH VIEN QUAN 7 | E17: 101 NGUYEN THI THAP, P.TAN PHU, QUAN 7, TPHCM | F17: RYZONAL (HOP/60VIEN) - EU | G17: 232652 | H17: NA | I17: 46367 | J17: hộp | K17: 1 | L17: Vỉ thuốc bên trong bị móp méo | M17: 03/04/2024 : nhận được hướng xử lý từ hãng và nhận công văn giải trình ---> Hoàn tất | N17: þ | O17: x
A18: 15 | B18: 45349 | C18: CC_150224 HUY | D18: BENH VIEN QUAN PHU NHUAN | E18: 274 NGUYEN TRONG TUYEN, PHUONG 8, QUAN PHU NHUAN, TP. HO CHI MINH | F18: LANTUS SOLOSTAR 100IU/ML B/5 PENS X 3ML | G18: 3F8891A | H18: 02/2023 | I18: 46053 | J18: Bút | K18: 1 | L18: Phần bấm của bút tiêm bị kẹt. Đây là bút mới, chưa bấm được nên chưa sử dụng (Khách hàng đã biết sử dụng Lantus và đã thực hiện các bước) | M18: - Gửi thông tin cho hãng ngày 27/02/2024 --> Hủy khiếu nại do khách không cung cấp được các chứng từ liên quan --> Hoàn tất | O18: x
A19: 16 | B19: 45350 | C19: CC_160224 | D19: KHOA DUOC BENH VIEN HUNG VUONG | E19: 128 HONG BANG, QUAN 5, TPHCM | F19: HEXAXIM BOX OF 1 PRE-FILLED SYRINGE + 2 NEEDLES | G19: NA | H19: NA | I19: NA | J19: NA | K19: NA | L19: Khi quét mã QR trên vỏ hộp sản phẩm Hexaxim, không hiển thị được thông tin sản phẩm | M19: - Đã báo hãng ngày 29/02/2024 - Nhận được câu trả lời từ hãng ngày 29/02/2024 --> Hoàn tất | O19: x
A20: 17 | B20: 45351 | C20: CC_170324 | D20: PHONG KHAM DA KHOA VICTORIA - CONG TY TNHH DUOC PHAM ATIPHARM | E20: 135A Nguyễn Văn Trỗi, Phú Nhuận TPHCM | F20: BRUFEN SUSPENSION 60ML | G20: 53247XP | H20: NA | I20: 46171 | J20: Chai | K20: 84 | L20: Khi mở hộp khui ra thì nắp bị nứt | M20: - Báo Plan complaint hãng - Đổi hàng cho khách - 21/03/2024: Hàng về kho --> Hoàn tất | O20: x
A21: 18 | B21: 45352 | C21: CC_180324 | D21: CONG TY TNHH DUOC PHAM MEDX | E21: TANG 1, SO 18 L1-5 VSIP II,DUONG SO 3, KCN VIET NAM-SINGAPORE II,HOA PHU, TP THU DAU MOT, BINH DUONG | F21: 1. Dầu gội 50 megumi ngăn ngừa rụng tóc (chai/250ml) 2. Sữa rửa mặt acnes vitamin cleanser rohto (t/50gr) | G21: 1.LZ01A 2.KZ01 | H21: NA | I21: 1.16/12/2026 2.06/11/2026 | J21: Chai Tuýp | K21: 1 | L21: Sản phẩm bị chảy Dính lem từ dầu gội | M21: - Đổi hàng cho khách - 18/03/2024: Hàng về kho --> Hoàn tất | O21: x
A22: 19 | B22: 45366 | C22: CC_190324-HUY | D22: BENH VIEN DA KHOA TAM ANH | E22: 2B Đ. Phổ Quang, Phường 2, Tân Bình, Thành phố Hồ Chí Minh | F22: APIDRA SOLOTAR 300UI/3ML | G22: 3F869A | H22: NA | I22: 45689 | J22: Bút | K22: 1 | L22: Khách hàng khi sử dụng bút tiêm phát hiện có cặn trắng bên trong ống đựng | M22: - Đã báo hãng ngày 15/03/2024 - Nhận được hướng xử lí ngày 19/03/2024 -02/04/2024: Bệnh viện xác nhận hủy ca khiếu nại này và không hỗ trợ thu mẫu ---> Hoàn tất | N22: þ | O22: x
A23: 20 | B23: 45376 | C23: CC_200324 | D23: BENH VIEN NHI DONG 2 | E23: 14 Lý Tự Trọng, Bến Nghé, Quận 1, Thành phố Hồ Chí Minh | F23: LOVENOX 40MG/0.4ML INJ. B/ 2 SYRINGES VN | G23: FS806A | H23: NA | I23: 45566 | J23: NA | K23: NA | L23: Điều kiện bảo quản được in trên nhãn thùng khác với thông tin được in trên hộp (Nhãn thùng: dưỡi 25 độ C Được in trên hộp: không quá 30 độ C) | M23: - Đã báo hãng ngày 25/03/2024 - Nhận được công văn phản hồi ngày 25/03/2024 và đã thông tin ngay cho khách hàng - Khách hàng yêu cầu thêm công văn (gửi bản giấy) --> Hoàn tất | O23: x
A24: 21 | B24: 45377 | C24: CC_210324 | D24: PHONG TIEM CHUNG VAC CIN NHAN AN | E24: 152, Quốc lộ 27, thôn 13, xã Ea Tiêu, huyện Cư Kuin, tỉnh Đắk Lắk | F24: HEXAXIM BOX OF 1 PRE-FILLED SYRINGE + 2 NEEDLES | G24: W3G601V | H24: NA | I24: 46142 | J24: Hộp | K24: 1 | L24: 1 hộp hexaxim bị thiếu lọ thuốc | M24: - Đã báo hãng ngày 26/03/2024 - Nhận được hướng xử lí ngày 26/03/2024 (đổi hàng và thu mẫu về VP Sanofi) - Xuất mẫu cho hãng ngày 30/07/2024 --> Hoàn tất | N24: þ | O24: x
A25: 22 | B25: 45378 | C25: CC_220324-HN | D25: CHI NHANH HA NOI-CONG TY CO PHAN DUOC PHAM FPT LONG CHAU | E25: TO DAN PHO 4, THI TRAN QUANG MINH, HUYEN ME LINH, HA NOI | F25: ALUMINIUMPHOSPHAT GEL (HOP/20 GOI) | G25: 221766 | H25: NA | I25: 19/08/2025 | J25: Hộp | K25: 1 | L25: Dung dịch thuốc bị rò rỉ thấm ra vỏ hộp | M25: 29/03/2024:Đã báo hãng 01/04/2024: Nhận được mail hãng yêu cầu gửi mẫu 1 hộp về hãng --> Hoàn tất | O25: x
A26: 23 | B26: 45379 | C26: CC_230324 | D26: CONG TY CO PHAN BENH CIEN DA KHOA MY DUC | E26: 79 Nguyễn Thị Nhỏ, Phường 9, Tân Bình, Thành phố Hồ Chí Minh | F26: CALCIUM CORBIERE EXTRA 3SUPX10 5ML VN | G26: DVH2160 | H26: NA | I26: 45736 | J26: Hộp | K26: 1 | L26: 1 hộp không có thuốc bên trong | M26: - Đã báo hãng ngày 28/03/2024 - Nhận được hướng xử lí ngày 01/04/2024 (đổi hàng và thu mẫu về VP Sanofi) --> Hoàn tất | N26: þ | O26: x
A27: 24 | B27: 45380 | C27: CC_240324 HUY | D27: NHA THUOC BENH VIEN DA KHOA TAM MINH DUC | E27: 177 Nguyễn Thái Sơn, Phường 4, Gò Vấp, Thành phố Hồ Chí Minh | F27: LANTUS SOLOSTAR 100IU/ML B/5 PENS X 3ML | G27: 2F8396A | H27: NA | I27: 01/2025 | J27: Bút | K27: 1 | L27: 1 bút Lantus không thể bấm xuống được | M27: 29/03/2024: Đã báo hãng 04/04/2024: Nhà thuốc đã kiểm tra và test lại thì bút Lantus đã sử dụng được bình thường, trước đây do lỗi bệnh nhân sử dụng kim bị cong đầu dưới, sau khi thay kim khác thì bút hoạt động tốt ---> Hủy khiếu nại ---> Hoàn tất | O27: x
A28: 25 | B28: 45380 | C28: CC_250324-HN-HUY | D28: CHI NHANH HA NOI-CONG TY CO PHAN DUOC PHAM FPT LONG CHAU | E28: TO DAN PHO 4, THI TRAN QUANG MINH, HUYEN ME LINH, HA NOI | F28: ALUMINIUMPHOSPHAT GEL (HOP/20 GOI) | G28: 221766 | H28: NA | I28: 19/08/2025 | J28: Hộp | K28: 1 | L28: Dung dịch thuốc bị rò rỉ thấm ra vỏ hộp | M28: Khách hàng hủy khiếu nại do không chờ được thời gian điều tra ---> Hoàn tất | O28: x
A29: 26 | B29: 45383 | C29: CC_260424-ĐN | D29: BENH VIEN DA KHOA KHU VUC BONG SON | E29: Số 2699 Quang Trung, phường Bồng Sơn, thị xã Hoài Nhơn, tỉnh Bình Định | F29: FORTRAGET | G29: 058M03 | H29: 27/05/2023 | I29: 27/05/2025 | J29: Lọ | K29: 1 | L29: Khi viện cấp cho bệnh nhân, test thử thì xịt không ra thuốc | M29: 01/04/2024: đã báo hãng 01/04/2024: Nhận được hướng xử lý ngày (đổi hàng cho khách và thu hồi mẫu về vp hãng ) --> Hoàn tất | O29: x
A30: 27 | B30: 45394 | C30: CC_270424 | D30: CONG TY TNHH TRUNG TAM Y KHOA PASTEUR DA LAT | E30: Số 16 đường Lê Hồng Phong, phường 4, Thành phố Đà Lạt, Lâm Đồng | F30: HEXAXIM BOX OF 1 PRE-FILLED SYRINGE + 2 NEEDLES | G30: W3G601V | H30: NA | I30: 30/04/2026 | J30: Hộp | K30: 1 | L30: Bị thiếu bơm tiêm | M30: 12/04/2024: đã báo hãng 12/04/2024: Nhận hướng xử lý (đổi hàng cho khách + mẫu thu về sẽ trả Sanofi theo đợt)--> Hoàn tất | O30: x
A31: 28 | B31: 45401 | C31: CC_280424 | D31: HO KINH DOANH PHONG KHAM 30 TRAN NHAT DUAT | E31: Số 30 Trần Nhật Duật, phường Tân Lợi, Tp. Buôn Ma Thuột, Đak Lak | F31: ENTEROGERMINA,4BCFU/5ML,SP,BT20,VN | G31: 3I154 | H31: 07/2023 | I31: 06/2025 | J31: Ống | K31: 10 | L31: Sản phẩm Enterogermina 4 tỷ bào tử có sự khác thường về mặt cảm quan: màu sắc thuốc ngả màu hơi vàng, có cặn đục màu hơi vàng ở đầu ống thuốc; có cát bụi, nấm mốc bao quanh bên ngoài vỏ ống thuốc và phía trong vỏ hộp. | M31: 19/04/2024: hãng gửi thông tin HĐ và xác nhận khiếu nại về chất lượng 20/04/2024: mail CS hướng xử lý (thu mẫu về vp sanofi + đổi hàng cho khách) 09/05/2024: nhập kho --> Hoàn tất | O31: x
A32: 29 | B32: 45404 | C32: CC_290424 | D32: TRUNG TAM Y TE HUYEN XUAN LOC | E32: NGA 3 SUOI CAT, XA SUOI CAT, H. XUAN LOC, DONG NAI | F32: TOUJEO SOLOSTAR 450IU B/5 PENS X 1.5ML | G32: 3F817A | H32: NA | I32: 45961 | J32: Bút | K32: 1 | L32: Bút tiêm bị phồng nút cao su | M32: 23/04/2024: đã báo hãng 26/04/2024: Nhận hướng xử lý (đổi hàng cho khách + mẫu thu về sẽ trả Sanofi theo đợt) --> Hoàn tất | O32: x
A33: 30 | B33: 45415 | C33: CC_300524 | D33: BENH VIEN UNG BUOU-CO SO 2 | E33: SO 12 DUONG 400, KHU PHO 3, PHUONG TAN PHU, THANH PHO THU DUC, TP. HO CHI MINH | F33: ZOLADEX 3.6 MG DEPOT 1'S | G33: SK762 | H33: NA | I33: 45837 | J33: Hộp | K33: 1 | L33: Khi bơm thuốc cho bệnh nhân thì phát hiện pít tông ống thuốc không bơm được | M33: 04/05/2024: đã báo hãng 07/05/2024: Nhận hướng xử lý ( đổi hàng cho khách + mẫu thu về sẽ trả AZ theo đợt) 10/05/2024: Nhập kho --> Hoàn tất | O33: x
A34: 31 | B34: 45419 | C34: CC_310524 | D34: BENH VIEN DA KHOA KHU VUC THU DUC | E34: 64 LE VAN CHI, PHUONG LINH TRUNG, THANH PHO THU DUC, TP. HO CHI MINH | F34: TARGOSID 400MG/3ML INJPO VLSX1 VN | G34: 1J5561 | H34: NA | I34: 31/05/2024 | J34: Lọ | K34: 23 | L34: Sản phẩm bị đổi màu | M34: 06/05/2024: đã báo hãng 03/07/2024: gửi mail chờ phản hồi từ KH 19/07/2024: KH chưa rep, mail remind 19/07/2024: Sau khi email đến hãng nhận được thông tin như sau" ca này Sanofi không đổi trả/ đền bù vì không có lỗi sản phẩm.Sanofi cũng đã hoàn tất điều tra và đóng khiếu nại theo quy trình nội bộ và phù hợp với luật định." Và Hoàng Đức cũng đã cố gắng liên hệ khách nhưng không nhận được phản hồi nào thêm Do đó QA sẽ close case này ---> Hoàn tất | O34: x
A35: 32 | B35: 45426 | C35: CC_320524 HUY | D35: TRUNG TAM Y TE HUYEN DON DUONG, LAM DONG | E35: 46 PHAM NGOC THACH, THANH MY, DON DUONG, LAM DONG | F35: LANTUS SOLOSTAR 100IU/ML B/5 PENS X 3ML | G35: 3F9097A | H35: NA | I35: 46142 | J35: Bút | K35: 2 | L35: Không bấm được | M35: 14/05/2024: đã báo hãng 28/05/2024: nhận hướng xử lý từ hãng (thu hồi + gửi mẫu về vp Sanofi) 30/05/2024: khách hủy khiếu nại do không còn yêu cầu hỗ trợ đổi trả hàng --> Hoàn tất | N35: þ | O35: x
A36: 33 | B36: 45429 | C36: CC_330524 | D36: CONG TY TNHH TRUNG TAM Y KHOA PASTEUR DA LAT | E36: SO 16 DUONG LE HONG PHONG, PHUONG 4, THANH PHO DA LAT, TINH LAM DONG | F36: WELLBABY MULTI-VITAMIN LIQUID (CHAI 150ML) | G36: 31308 | H36: NA | I36: 45869 | J36: Hộp | K36: 1 | L36: Bị rách vỏ hộp | M36: 17/05/2024: đã báo hãng VE 20/05/2024: nhận hướng xử lý từ hãng (đổi hàng + nhập kho damage chờ xử lý) 27/05/2024: nhập kho ---> Hoàn tất | O36: x
A37: 34 | B37: 45433 | C37: CC_340524 | D37: BVDK LONG AN | E37: 211 NGUYEN THONG, PHUONG 3, TP TAN AN , TINH LONG AN | F37: DEPAKINE 200MG TABEC TB40 | G37: 2RX28 | H37: NA | I37: 11/2025 | J37: Hộp | K37: 1 | L37: Sản phẩm bị nứt ngoài vỏ hộp nhựa và thuốc bị chảy, ẩm ướt | M37: 21/05/2024: đã báo hãng + nhận hướng xử lý (đổi hàng + trả hàng theo đợt) 18/06/2024: nhập kho --> Hoàn tất | O37: x
A38: 35 | B38: 45433 | C38: CC_350524 | D38: CONG TY CO PHAN Y TE CHAN VAN | E38: 541/21 SU VAN HANH, PHUONG 13, QUAN TAN BINH, TP. HO CHI MINH | F38: ADACEL BOX OF 1 VIAL | G38: 2CA07C3 | H38: NA | I38: 45596 | J38: Hộp | K38: 1 | L38: Vaccine có mảng trắng và lắc không tan | M38: 21/05/2024: đã báo hãng + nhận khiếu nại 27/05/2024: hãng báo thu mẫu về vp Sanofi 18/06/2024: nhập kho--> Hoàn tất | N38: þ | O38: x
A39: 36 | B39: 45443 | C39: CC_360524 | D39: BENH VIEN BA RIA VUNG TAU | E39: 686 DUONG VO VAN KIET, PHUONG LONG TAM, THANH PHO BA RIA, TINH BA RIA VUNG TAU | F39: THUC PHAM DINH DUONG Y HOC FORTIMEL PROTEIN (HUONG VANI) | G39: 111341678 111325237 | H39: 31/01/2024 05/12/2023 | I39: 30/01/2025 04/12/2024 | J39: Chai | K39: 1 | L39: Có lẫn 1 chai lô 111325237 trong lốc lô 111341678 | M39: 04/06/2024: đã báo hãng Danone 21/06/2024: nhận phản hồi từ hãng --> Hoàn tất | O39: x
A40: 37 | B40: 45443 | C40: CC_370524 | D40: KHOA DUOC BENH VIEN VIET PHAP | E40: SO 1 PHUONG MAI - DONG DA - HN | F40: THUC PHAM DINH DUONG Y HOC FORTIMEL PROTEIN (HUONG VANI) | G40: 111341678 | H40: 31/01/2024 | I40: 30/01/2025 | J40: Chai | K40: NA | L40: Số lô trên chai và lốc khác nhau, nhưng cùng hạn dùng | M40: 04/06/2024: đã báo hãng Danone 21/06/2024: nhận phản hồi từ hãng --> Hoàn tất | O40: x
A41: 38 | B41: 45448 | C41: CC_380624 | D41: CÔNG TY TNHH THƯƠNG MẠI VÀ DƯỢC PHẨM SANG | E41: 11/9 Ngô Quang Huy, Phường Thảo Điền, Tp.Thủ Đức, Tp.Hồ Chí Minh | F41: IMOJEV 0.5ML 1DOSE | G41: 08A2306GA 08A2305GA | H41: NA | I41: 22/05/2026 15/05/2026 | J41: Lọ | K41: 2 | L41: Thể tích dung môi dư 0,1ml so với quy định. | M41: 06/06/2024: đã báo Sanofi 03/07/2024: chờ phản hồi email từ hãng 26/07/2024: nhận được phản hồi từ nhà máy SNF 29/07/2024: khách confirm đã nhận thông tin ---> Hoàn tất | O41: x
...

Sheet ver 10-CC_650824
D1: BIỂU MẪU 02/ FORM 02 DANH SÁCH KHIẾU NẠI KHÁCH HÀNG NĂM 2024 LIST OF CUSTOMER COMPLAINTS - YEAR 2024
A3: STT No. | B3: Ngày date | C3: Code CC- | D3: Tên khách hàng Customer | E3: Địa chỉ address | F3: Tên sản phẩm Product name | G3: Số Lô batch No. | H3: NSX Mfg date | I3: HD Exp date | J3: Đơn vị tính Unit | K3: Số Lượng Quanity | L3: Lý do khiếu nại Reason of complaint | M3: Nguyên nhân khiếu nại/ Cause of complaint | N3: Tình trạng status | O3: Xuất mẫu sang văn phòng hãng | P3: BẢO MẬT THÔNG TIN CÁ NHÂN | Q3: HÌNH THỨC NHẬN
A4: =ROW(B4)-3 -> 1 | B4: 45295 | C4: CC_010124 | D4: CHI NHANH HA NOI-CONG TY CO PHAN DUOC PHAM FPT LONG CHAU | E4: TO DAN PHO 4, THI TRAN QUANG MINH, HUYEN ME LINH, HA NOI | F4: PLENDIL PLUS 5/50 MG PROLONGED-RELEASE TABLET BOTTLE 30'S | G4: MANS | H4: NA | I4: 45584 | J4: Hộp | K4: 1 | L4: Vỏ ngoài hộp thuốc có lô MANS date 19/10/2024 Bên trong hộp thuốc lại có lô MANC hạn là 16/11/2023 (HẾT HẠN) | M4: NA | N4: - Do hàng mua từ CÔNG TY TNHH THƯƠNG MẠI VÀ DP SANG nên Plan sẽ gửi thông tin cho CÔNG TY TNHH THƯƠNG MẠI VÀ DP SANG về complaint này - Nhận được phản hồi từ nhà sản xuất ngày 25/01/2024--> Lỗi không từ nhà sản xuất - Tiến hành đổi trả cho khách -->Hoàn tất | O4: þ
A5: =ROW(B5)-3 -> 2 | B5: 45296 | C5: CC_020124 | D5: BENH VIEN TAM THAN | E5: 766 VO VAN KIET, P1, QUAN 5, TP. HCM | F5: DEPAKINE CHRONO 500MG TUBE OF 30 TABS VN | G5: EA3158 | H5: NA | I5: 46174 | J5: Hộp | K5: 1 | L5: Hộp bị nứt, thuốc bị dính nhau (có đính kèm hình ảnh, video) | M5: NA | N5: - Đã báo hãng - Nhận được hướng xử lý ngày 08/01/2024 - Ngày 15/01/2024, hàng khiếu nại về kho -->Hoàn tất
A6: =ROW(B6)-3 -> 3 | B6: 45301 | C6: CC_030124 HUY | D6: BENH VIEN VUNG TAU | E6: SO 27, DUONG 2/9 PHUONG 11, THANH PHO VUNG TAU, TINH BA RIA VUNG TAU | F6: LANTUS SOLOSTAR 100IU/ML B/5 PENS X 3ML | G6: 3F8891A | H6: NA | I6: 46053 | J6: Bút | K6: 1 | L6: Một bút Lantus Solostar không tiêm được | M6: NA | N6: - Đã báo hãng - Hãng không chấp nhận khiếu nại do kim novofine 31g 6mm không nằm trong danh sách kim tiêm tương thích với Lantus Solostar - Ngày 16/01/2024, sau khi trao đổi, thu mẫu của khách gửi nhà máy điều tra, sau khi có kết quả điều tra từ nhà máy mới tiến hành đền bù với khách Nhận được hướng xử lý ngày 11/01/2024 --> Hủy khiếu nại do khách không thể cung cấp chứng từ theo yêu cầu --> Hoàn tất | O6: þ
A7: =ROW(B7)-3 -> 4 | B7: 45300 | C7: CC_040124-HN | D7: CONG TY CO PHAN DAU TU DICH VU Y TE THE MEDCARE – CN HAI PHONG | E7: TẦNG 3-4 TÒA NHÀ DUY KHÁNH, SỐ 2 LÔ 22, PHƯỜNG ĐÔNG KHÊ, QUẬN NGÔ QUYỀN, HẢI PHÒNG | F7: BRUFEN SUSPENSION 60ML | G7: 53246XP | H7: NA | I7: 46169 | J7: Hộp | K7: 19 | L7: Sản phẩm bị lỗi bung nắp | M7: NA | N7: - khiếu nại lặp lại xử lý như CC_641123 | O7: þ
A8: =ROW(B8)-3 -> 5 | B8: 45303 | C8: CC_050124 | D8: HO KINH DOANH CHERRY SHOP | E8: DUONG CHU VAN AN, THON HIEP HOA, XA TAN HAI, THI XA LA GI, TINH BINH THUAN | F8: FONTACTIV® COMPLETE (VANILLA 800G) | G8: 3062-146 | H8: NA | I8: 45963 | J8: Lon | K8: 2 | L8: Sản phẩm bị móp trong thùng nguyên | M8: NA | N8: - Báo Plan complaint hãng - Nhận được hướng xuất mẫu cho hãng ngày 16/01/2024 Ngày 22/01/2024 hàng khiếu nại về kho -->Hoàn tất | O8: þ
A9: =ROW(B9)-3 -> 6 | B9: 45303 | C9: CC_060124 | D9: PHONG KHAM DA KHOA VICTORIA - CONG TY TNHH DUOC PHAM ATIPHARM | E9: 20 -20 BIS - 22 DINH TIEN HOANG, PHUONG DA KAO, QUAN 1, THANH PHO HO CHI MINH | F9: BRUFEN SUSPENSION 60ML | G9: 53246XP | H9: NA | I9: 46169 | J9: Hộp | K9: 34 | L9: Sản phẩm bị lỗi bung nắp | M9: NA | N9: Gửi trả hãng như các khiếu nại trước --->Hoàn tất | O9: þ
A10: =ROW(B10)-3 -> 7 | B10: 45309 | C10: CC_070124-HN | D10: BENH VIEN K TAN TRIEU | E10: 30 Đ. CẦU BƯƠU, TÂN TRIỀU, THANH TRÌ, HÀ NỘI | F10: ERANFU | G10: K230144 | H10: NA | I10: 45658 | J10: Hộp | K10: 1 | L10: Lỗi không có kim tiêm | M10: NA | N10: - Hàng được điều chuyển về kho LH để hủy --> Hoàn tất
A11: =ROW(B11)-3 -> 8 | B11: 45321 | C11: CC_080124 | D11: NHA THUOC TAY THANG | E11: 129 NGUYEN TRAI, DIEN KHANH, KHANH HOA | F11: BRUFEN SUSPENSION 60ML | G11: 53246XP | H11: NA | I11: 46169 | J11: Hộp | K11: 3 | L11: Sản phẩm bị lỗi bung nắp | M11: NA | N11: Gửi trả hãng như các khiếu nại trước --->Hoàn tất | O11: þ
A12: =ROW(B12)-3 -> 9 | B12: 45323 | C12: CC_090224 | D12: KHACH HANG VANG LAI-HCM | E12: 12 NGUYEN HIEN, P4, QUAN 3, TP.HCM | F12: C SCAPE+ SERUM 30ML | G12: WG0208 | H12: NA | I12: 45991 | J12: Hộp | K12: 1 | L12: Tình trạng không đóng nắp chai kỹ, bị rò rỉ dung dịch ướt cả bên trong hộp | M12: NA | N12: -Gửi hãng thông tin - Chấp nhận đổi hàng cho khách - Hướng xử lý và đền bù hãng sẽ thông báo sau. Chi phí đền bù ban đầu sẽ charge vào chi phí công ty --->Hoàn tất
A13: =ROW(B13)-3 -> 10 | B13: 45327 | C13: CC_100224 | D13: NHA THUOC PHONG KHAM DA KHOA MINH HAI | E13: 214 LY THUONG KIET, KHOM 3, PHUONG 6, THANH PHO CA MAU, TINH CA MAU | F13: BRUFEN SUSPENSION 60ML | G13: 53247XP | H13: NA | I13: 46171 | J13: Hộp | K13: 3 | L13: Khi mở hộp khui ra thì nắp bị nứt | M13: NA | N13: Gửi trả hãng như các khiếu nại trước --->Hoàn tất | O13: þ
A14: =ROW(B14)-3 -> 11 | B14: 45341 | C14: CC_110224 | D14: PHONG TIEM CHUNG TANIMED | E14: SO 73, DUONG 30/04, PHUONG 3, TP. TAY NINH, TINH TAY NINH | F14: MENACTRA BOX OF 1 VIAL | G14: U7771BC | H14: NA | I14: 45535 | J14: Hộp | K14: 1 | L14: Không có thuốc | M14: NA | N14: -Gửi hãng thông tin - Ngày 19/02/2024, hãng chấp nhận khiếu nại 22/04 mẫu về kho ---> Hoàn tất | O14: þ
A15: =ROW(B15)-3 -> 12 | B15: 45341 | C15: CC_120224 | D15: BENH VIEN TAM THAN | E15: 766 VO VAN KIET, P1, QUAN 5, TP. HCM | F15: DEPAKINE CHRONO 500MG TUBE OF 30 TABS VN | G15: EA3159 | H15: 07/2023 | I15: 46174 | J15: Hộp | K15: 1 | L15: Trong hộp có 1 viên bị nứt đôi, chỉ phát hiện nửa viên, không phát hiện nửa viên còn lại | M15: NA | N15: -Gửi hãng thông tin - Nhận được hướng xử lý 20/02/2024 - Ngày 29/02/2024, hàng khiếu nại về kho, phát hiện số lô lọ và số lô trên hộp không khớp với nhau. Lý do khách báo nhầm lô. Báo email cho hãng cập nhật thông tin --->Hoàn tất
A16: =ROW(B16)-3 -> 13 | B16: 45341 | C16: CC_130224-HUY | D16: CHI NHANH CONG TY CO PHAN BENH VIEN DA KHOA TAM ANH TP. HO CHI MINH - KHOA DUOC (BVTP) | E16: 2B PHO QUANG, PHUONG 2, QUAN TAN BINH, TP. HO CHI MINH, VIET NAM | F16: TOUJEO SOLOSTAR 450IU B/5 PENS X 1.5ML | G16: 3F599A | H16: NA | I16: 45777 | J16: Bút | K16: 1 | L16: Sử dụng bút tiêm Toujeo Solostar với liều 18UI/ngày, dùng kim tiêm Novofine 6 mm, sau khi tiêm thì thấy máu xuất hiện trong uống chứa thuốc, lắc thì máu tan ra hết | M16: NA | N16: -Gửi hãng thông tin ngày 19/02/2024 - Hãng chấp nhận khiếu nại 03/04/2024: Hủy khiếu nại do khách đồng ý thu hồi mẫu, và cũng không yêu cầu đổi hàng --->Hoàn tất | O16: þ
A17: =ROW(B17)-3 -> 14 | B17: 45348 | C17: CC_140224 | D17: BENH VIEN QUAN 7 | E17: 101 NGUYEN THI THAP, P.TAN PHU, QUAN 7, TPHCM | F17: RYZONAL (HOP/60VIEN) - EU | G17: 232652 | H17: NA | I17: 46367 | J17: hộp | K17: 1 | L17: Vỉ thuốc bên trong bị móp méo | M17: NA | N17: 03/04/2024 : nhận được hướng xử lý từ hãng và nhận công văn giải trình ---> Hoàn tất | O17: þ
A18: =ROW(B18)-3 -> 15 | B18: 45349 | C18: CC_150224 HUY | D18: BENH VIEN QUAN PHU NHUAN | E18: 274 NGUYEN TRONG TUYEN, PHUONG 8, QUAN PHU NHUAN, TP. HO CHI MINH | F18: LANTUS SOLOSTAR 100IU/ML B/5 PENS X 3ML | G18: 3F8891A | H18: 02/2023 | I18: 46053 | J18: Bút | K18: 1 | L18: Phần bấm của bút tiêm bị kẹt. Đây là bút mới, chưa bấm được nên chưa sử dụng (Khách hàng đã biết sử dụng Lantus và đã thực hiện các bước) | M18: NA | N18: - Gửi thông tin cho hãng ngày 27/02/2024 --> Hủy khiếu nại do khách không cung cấp được các chứng từ liên quan --> Hoàn tất
A19: =ROW(B19)-3 -> 16 | B19: 45350 | C19: CC_160224 | D19: KHOA DUOC BENH VIEN HUNG VUONG | E19: 128 HONG BANG, QUAN 5, TPHCM | F19: HEXAXIM BOX OF 1 PRE-FILLED SYRINGE + 2 NEEDLES | G19: NA | H19: NA | I19: NA | J19: NA | K19: NA | L19: Khi quét mã QR trên vỏ hộp sản phẩm Hexaxim, không hiển thị được thông tin sản phẩm | M19: NA | N19: - Đã báo hãng ngày 29/02/2024 - Nhận được câu trả lời từ hãng ngày 29/02/2024 --> Hoàn tất
A20: =ROW(B20)-3 -> 17 | B20: 45351 | C20: CC_170324 | D20: PHONG KHAM DA KHOA VICTORIA - CONG TY TNHH DUOC PHAM ATIPHARM | E20: 135A Nguyễn Văn Trỗi, Phú Nhuận TPHCM | F20: BRUFEN SUSPENSION 60ML | G20: 53247XP | H20: NA | I20: 46171 | J20: Chai | K20: 84 | L20: Khi mở hộp khui ra thì nắp bị nứt | M20: NA | N20: - Báo Plan complaint hãng - Đổi hàng cho khách - 21/03/2024: Hàng về kho --> Hoàn tất
A21: =ROW(B21)-3 -> 18 | B21: 45352 | C21: CC_180324 | D21: CONG TY TNHH DUOC PHAM MEDX | E21: TANG 1, SO 18 L1-5 VSIP II,DUONG SO 3, KCN VIET NAM-SINGAPORE II,HOA PHU, TP THU DAU MOT, BINH DUONG | F21: 1. Dầu gội 50 megumi ngăn ngừa rụng tóc (chai/250ml) 2. Sữa rửa mặt acnes vitamin cleanser rohto (t/50gr) | G21: 1.LZ01A 2.KZ01 | H21: NA | I21: 1.16/12/2026 2.06/11/2026 | J21: Chai Tuýp | K21: 1 | L21: Sản phẩm bị chảy Dính lem từ dầu gội | M21: NA | N21: - Đổi hàng cho khách - 18/03/2024: Hàng về kho --> Hoàn tất
A22: =ROW(B22)-3 -> 19 | B22: 45366 | C22: CC_190324-HUY | D22: BENH VIEN DA KHOA TAM ANH | E22: 2B PHO QUANG, PHUONG 2, QUAN TAN BINH, TP. HO CHI MINH, VIET NAM | F22: APIDRA SOLOTAR 300UI/3ML | G22: 3F869A | H22: NA | I22: 45689 | J22: Bút | K22: 1 | L22: Khách hàng khi sử dụng bút tiêm phát hiện có cặn trắng bên trong ống đựng | M22: NA | N22: - Đã báo hãng ngày 15/03/2024 - Nhận được hướng xử lí ngày 19/03/2024 -02/04/2024: Bệnh viện xác nhận hủy ca khiếu nại này và không hỗ trợ thu mẫu ---> Hoàn tất | O22: þ
A23: =ROW(B23)-3 -> 20 | B23: 45376 | C23: CC_200324 | D23: BENH VIEN NHI DONG 2 | E23: 14 Lý Tự Trọng, Bến Nghé, Quận 1, Thành phố Hồ Chí Minh | F23: LOVENOX 40MG/0.4ML INJ. B/ 2 SYRINGES VN | G23: FS806A | H23: NA | I23: 45566 | J23: NA | K23: NA | L23: Điều kiện bảo quản được in trên nhãn thùng khác với thông tin được in trên hộp (Nhãn thùng: dưỡi 25 độ C Được in trên hộp: không quá 30 độ C) | M23: NA | N23: - Đã báo hãng ngày 25/03/2024 - Nhận được công văn phản hồi ngày 25/03/2024 và đã thông tin ngay cho khách hàng - Khách hàng yêu cầu thêm công văn (gửi bản giấy) --> Hoàn tất
A24: =ROW(B24)-3 -> 21 | B24: 45377 | C24: CC_210324 | D24: PHONG TIEM CHUNG VAC CIN NHAN AN | E24: 152, Quốc lộ 27, thôn 13, xã Ea Tiêu, huyện Cư Kuin, tỉnh Đắk Lắk | F24: HEXAXIM BOX OF 1 PRE-FILLED SYRINGE + 2 NEEDLES | G24: W3G601V | H24: NA | I24: 46142 | J24: Hộp | K24: 1 | L24: 1 hộp hexaxim bị thiếu lọ thuốc | M24: NA | N24: - Đã báo hãng ngày 26/03/2024 - Nhận được hướng xử lí ngày 26/03/2024 (đổi hàng và thu mẫu về VP Sanofi) - Xuất mẫu cho hãng ngày 30/07/2024 --> Hoàn tất | O24: þ
A25: =ROW(B25)-3 -> 22 | B25: 45378 | C25: CC_220324-HN | D25: CHI NHANH HA NOI-CONG TY CO PHAN DUOC PHAM FPT LONG CHAU | E25: TO DAN PHO 4, THI TRAN QUANG MINH, HUYEN ME LINH, HA NOI | F25: ALUMINIUMPHOSPHAT GEL (HOP/20 GOI) | G25: 221766 | H25: NA | I25: 19/08/2025 | J25: Hộp | K25: 1 | L25: Dung dịch thuốc bị rò rỉ thấm ra vỏ hộp | M25: NA | N25: 29/03/2024:Đã báo hãng 01/04/2024: Nhận được mail hãng yêu cầu gửi mẫu 1 hộp về hãng --> Hoàn tất
A26: =ROW(B26)-3 -> 23 | B26: 45379 | C26: CC_230324 | D26: CONG TY CO PHAN BENH CIEN DA KHOA MY DUC | E26: 79 Nguyễn Thị Nhỏ, Phường 9, Tân Bình, Thành phố Hồ Chí Minh | F26: CALCIUM CORBIERE EXTRA 3SUPX10 5ML VN | G26: DVH2160 | H26: NA | I26: 45736 | J26: Hộp | K26: 1 | L26: 1 hộp không có thuốc bên trong | M26: NA | N26: - Đã báo hãng ngày 28/03/2024 - Nhận được hướng xử lí ngày 01/04/2024 (đổi hàng và thu mẫu về VP Sanofi) --> Hoàn tất | O26: þ
A27: =ROW(B27)-3 -> 24 | B27: 45380 | C27: CC_240324 HUY | D27: NHA THUOC BENH VIEN DA KHOA TAM MINH DUC | E27: 177 Nguyễn Thái Sơn, Phường 4, Gò Vấp, Thành phố Hồ Chí Minh | F27: LANTUS SOLOSTAR 100IU/ML B/5 PENS X 3ML | G27: 2F8396A | H27: NA | I27: 01/2025 | J27: Bút | K27: 1 | L27: 1 bút Lantus không thể bấm xuống được | M27: NA | N27: 29/03/2024: Đã báo hãng 04/04/2024: Nhà thuốc đã kiểm tra và test lại thì bút Lantus đã sử dụng được bình thường, trước đây do lỗi bệnh nhân sử dụng kim bị cong đầu dưới, sau khi thay kim khác thì bút hoạt động tốt ---> Hủy khiếu nại ---> Hoàn tất
A28: =ROW(B28)-3 -> 25 | B28: 45380 | C28: CC_250324-HN-HUY | D28: CHI NHANH HA NOI-CONG TY CO PHAN DUOC PHAM FPT LONG CHAU | E28: TO DAN PHO 4, THI TRAN QUANG MINH, HUYEN ME LINH, HA NOI | F28: ALUMINIUMPHOSPHAT GEL (HOP/20 GOI) | G28: 221766 | H28: NA | I28: 19/08/2025 | J28: Hộp | K28: 1 | L28: Dung dịch thuốc bị rò rỉ thấm ra vỏ hộp | M28: NA | N28: Khách hàng hủy khiếu nại do không chờ được thời gian điều tra ---> Hoàn tất
A29: =ROW(B29)-3 -> 26 | B29: 45383 | C29: CC_260424-ĐN | D29: BENH VIEN DA KHOA KHU VUC BONG SON | E29: Số 2699 Quang Trung, phường Bồng Sơn, thị xã Hoài Nhơn, tỉnh Bình Định | F29: FORTRAGET | G29: 058M03 | H29: 27/05/2023 | I29: 27/05/2025 | J29: Lọ | K29: 1 | L29: Khi viện cấp cho bệnh nhân, test thử thì xịt không ra thuốc | M29: NA | N29: 01/04/2024: đã báo hãng 01/04/2024: Nhận được hướng xử lý ngày (đổi hàng cho khách và thu hồi mẫu về vp hãng ) --> Hoàn tất
A30: =ROW(B30)-3 -> 27 | B30: 45394 | C30: CC_270424 | D30: CONG TY TNHH TRUNG TAM Y KHOA PASTEUR DA LAT | E30: Số 16 đường Lê Hồng Phong, phường 4, Thành phố Đà Lạt, Lâm Đồng | F30: HEXAXIM BOX OF 1 PRE-FILLED SYRINGE + 2 NEEDLES | G30: W3G601V | H30: NA | I30: 30/04/2026 | J30: Hộp | K30: 1 | L30: Bị thiếu bơm tiêm | M30: NA | N30: 12/04/2024: đã báo hãng 12/04/2024: Nhận hướng xử lý (đổi hàng cho khách + mẫu thu về sẽ trả Sanofi theo đợt)--> Hoàn tất
A31: =ROW(B31)-3 -> 28 | B31: 45401 | C31: CC_280424 | D31: HO KINH DOANH PHONG KHAM 30 TRAN NHAT DUAT | E31: Số 30 Trần Nhật Duật, phường Tân Lợi, Tp. Buôn Ma Thuột, Đak Lak | F31: ENTEROGERMINA,4BCFU/5ML,SP,BT20,VN | G31: 3I154 | H31: 07/2023 | I31: 06/2025 | J31: Ống | K31: 10 | L31: Sản phẩm Enterogermina 4 tỷ bào tử có sự khác thường về mặt cảm quan: màu sắc thuốc ngả màu hơi vàng, có cặn đục màu hơi vàng ở đầu ống thuốc; có cát bụi, nấm mốc bao quanh bên ngoài vỏ ống thuốc và phía trong vỏ hộp. | M31: NA | N31: 19/04/2024: hãng gửi thông tin HĐ và xác nhận khiếu nại về chất lượng 20/04/2024: mail CS hướng xử lý (thu mẫu về vp sanofi + đổi hàng cho khách) 09/05/2024: nhập kho --> Hoàn tất
A32: =ROW(B32)-3 -> 29 | B32: 45404 | C32: CC_290424 | D32: TRUNG TAM Y TE HUYEN XUAN LOC | E32: NGA 3 SUOI CAT, XA SUOI CAT, H. XUAN LOC, DONG NAI | F32: TOUJEO SOLOSTAR 450IU B/5 PENS X 1.5ML | G32: 3F817A | H32: NA | I32: 45961 | J32: Bút | K32: 1 | L32: Bút tiêm bị phồng nút cao su | M32: NA | N32: 23/04/2024: đã báo hãng 26/04/2024: Nhận hướng xử lý (đổi hàng cho khách + mẫu thu về sẽ trả Sanofi theo đợt) --> Hoàn tất
A33: =ROW(B33)-3 -> 30 | B33: 45415 | C33: CC_300524 | D33: BENH VIEN UNG BUOU-CO SO 2 | E33: SO 12 DUONG 400, KHU PHO 3, PHUONG TAN PHU, THANH PHO THU DUC, TP. HO CHI MINH | F33: ZOLADEX 3.6 MG DEPOT 1'S | G33: SK762 | H33: NA | I33: 45837 | J33: Hộp | K33: 1 | L33: Khi bơm thuốc cho bệnh nhân thì phát hiện pít tông ống thuốc không bơm được | M33: NA | N33: 04/05/2024: đã báo hãng 07/05/2024: Nhận hướng xử lý ( đổi hàng cho khách + mẫu thu về sẽ trả AZ theo đợt) 10/05/2024: Nhập kho --> Hoàn tất
A34: =ROW(B34)-3 -> 31 | B34: 45419 | C34: CC_310524 | D34: BENH VIEN DA KHOA KHU VUC THU DUC | E34: 64 LE VAN CHI, PHUONG LINH TRUNG, THANH PHO THU DUC, TP. HO CHI MINH | F34: TARGOSID 400MG/3ML INJPO VLSX1 VN | G34: 1J5561 | H34: NA | I34: 31/05/2024 | J34: Lọ | K34: 23 | L34: Sản phẩm bị đổi màu | M34: NA | N34: 06/05/2024: đã báo hãng 03/07/2024: gửi mail chờ phản hồi từ KH 19/07/2024: KH chưa rep, mail remind 19/07/2024: Sau khi email đến hãng nhận được thông tin như sau" ca này Sanofi không đổi trả/ đền bù vì không có lỗi sản phẩm.Sanofi cũng đã hoàn tất điều tra và đóng khiếu nại theo quy trình nội bộ và phù hợp với luật định." Và Hoàng Đức cũng đã cố gắng liên hệ khách nhưng không nhận được phản hồi nào thêm Do đó QA sẽ close case này ---> Hoàn tất
A35: =ROW(B35)-3 -> 32 | B35: 45426 | C35: CC_320524 HUY | D35: TRUNG TAM Y TE HUYEN DON DUONG, LAM DONG | E35: 46 PHAM NGOC THACH, THANH MY, DON DUONG, LAM DONG | F35: LANTUS SOLOSTAR 100IU/ML B/5 PENS X 3ML | G35: 3F9097A | H35: NA | I35: 46142 | J35: Bút | K35: 2 | L35: Không bấm được | M35: NA | N35: 14/05/2024: đã báo hãng 28/05/2024: nhận hướng xử lý từ hãng (thu hồi + gửi mẫu về vp Sanofi) 30/05/2024: khách hủy khiếu nại do không còn yêu cầu hỗ trợ đổi trả hàng --> Hoàn tất | O35: þ
A36: =ROW(B36)-3 -> 33 | B36: 45429 | C36: CC_330524 | D36: CONG TY TNHH TRUNG TAM Y KHOA PASTEUR DA LAT | E36: SO 16 DUONG LE HONG PHONG, PHUONG 4, THANH PHO DA LAT, TINH LAM DONG | F36: WELLBABY MULTI-VITAMIN LIQUID (CHAI 150ML) | G36: 31308 | H36: NA | I36: 45869 | J36: Hộp | K36: 1 | L36: Bị rách vỏ hộp | M36: NA | N36: 17/05/2024: đã báo hãng VE 20/05/2024: nhận hướng xử lý từ hãng (đổi hàng + nhập kho damage chờ xử lý) 27/05/2024: nhập kho ---> Hoàn tất
A37: =ROW(B37)-3 -> 34 | B37: 45433 | C37: CC_340524 | D37: BVDK LONG AN | E37: 211 NGUYEN THONG, PHUONG 3, TP TAN AN , TINH LONG AN | F37: DEPAKINE 200MG TABEC TB40 | G37: 2RX28 | H37: NA | I37: 11/2025 | J37: Hộp | K37: 1 | L37: Sản phẩm bị nứt ngoài vỏ hộp nhựa và thuốc bị chảy, ẩm ướt | M37: NA | N37: 21/05/2024: đã báo hãng + nhận hướng xử lý (đổi hàng + trả hàng theo đợt) 18/06/2024: nhập kho --> Hoàn tất
A38: =ROW(B38)-3 -> 35 | B38: 45433 | C38: CC_350524 | D38: CONG TY CO PHAN Y TE CHAN VAN | E38: 541/21 SU VAN HANH, PHUONG 13, QUAN TAN BINH, TP. HO CHI MINH | F38: ADACEL BOX OF 1 VIAL | G38: 2CA07C3 | H38: NA | I38: 45596 | J38: Hộp | K38: 1 | L38: Vaccine có mảng trắng và lắc không tan | M38: NA | N38: 21/05/2024: đã báo hãng + nhận khiếu nại 27/05/2024: hãng báo thu mẫu về vp Sanofi 18/06/2024: nhập kho--> Hoàn tất | O38: þ
A39: =ROW(B39)-3 -> 36 | B39: 45443 | C39: CC_360524 | D39: BENH VIEN BA RIA VUNG TAU | E39: 686 DUONG VO VAN KIET, PHUONG LONG TAM, THANH PHO BA RIA, TINH BA RIA VUNG TAU | F39: THUC PHAM DINH DUONG Y HOC FORTIMEL PROTEIN (HUONG VANI) | G39: 111341678 111325237 | H39: 31/01/2024 05/12/2023 | I39: 30/01/2025 04/12/2024 | J39: Chai | K39: 1 | L39: Có lẫn 1 chai lô 111325237 trong lốc lô 111341678 | M39: NA | N39: 04/06/2024: đã báo hãng Danone 21/06/2024: nhận phản hồi từ hãng --> Hoàn tất
A40: =ROW(B40)-3 -> 37 | B40: 45443 | C40: CC_370524 | D40: KHOA DUOC BENH VIEN VIET PHAP | E40: SO 1 PHUONG MAI - DONG DA - HN | F40: THUC PHAM DINH DUONG Y HOC FORTIMEL PROTEIN (HUONG VANI) | G40: 111341678 | H40: 31/01/2024 | I40: 30/01/2025 | J40: Chai | K40: NA | L40: Số lô trên chai và lốc khác nhau, nhưng cùng hạn dùng | M40: NA | N40: 04/06/2024: đã báo hãng Danone 21/06/2024: nhận phản hồi từ hãng --> Hoàn tất
A41: =ROW(B41)-3 -> 38 | B41: 45448 | C41: CC_380624 | D41: CÔNG TY TNHH THƯƠNG MẠI VÀ DƯỢC PHẨM SANG | E41: 11/9 Ngô Quang Huy, Phường Thảo Điền, Tp.Thủ Đức, Tp.Hồ Chí Minh | F41: IMOJEV 0.5ML 1DOSE | G41: 08A2306GA 08A2305GA | H41: NA | I41: 22/05/2026 15/05/2026 | J41: Lọ | K41: 2 | L41: Thể tích dung môi dư 0,1ml so với quy định. | M41: NA | N41: 06/06/2024: đã báo Sanofi 03/07/2024: chờ phản hồi email từ hãng 26/07/2024: nhận được phản hồi từ nhà máy SNF 29/07/2024: khách confirm đã nhận thông tin ---> Hoàn tất
...

Sheet 2025
D1: BIỂU MẪU 02/ FORM 02 DANH SÁCH KHIẾU NẠI KHÁCH HÀNG NĂM 2024 LIST OF CUSTOMER COMPLAINTS - YEAR 2024
A3: STT No. | B3: Ngày date | C3: Code CC- | D3: Tên khách hàng Customer | E3: Địa chỉ address | F3: Tên sản phẩm Product name | G3: Số Lô batch No. | H3: NSX Mfg date | I3: HD Exp date | J3: Đơn vị tính Unit | K3: Số Lượng Quanity | L3: Lý do khiếu nại Reason of complaint | M3: Nguyên nhân khiếu nại/ Cause of complaint | N3: Tình trạng status | O3: Xuất mẫu sang văn phòng hãng | P3: BẢO MẬT THÔNG TIN CÁ NHÂN | Q3: HÌNH THỨC NHẬN | R3: XÁC NHẬN TỪ HÃNG | S3: NGÀY NHẬN | T3: FIXED EXP | U3: FIXED IMPORT
A4: =ROW(B4)-3 -> 1 | B4: 45660 | C4: CC_010125-HCM HUY | D4: CONG TY CO PHAN BENH VIEN DA KHOA HOAN MY DA LAT | E4: DOI LONG THO, P10, TP DA LAT, TINH LAM DONG | F4: TOUJEO SOLOSTAR 450IU B/5 PENS X 1.5ML | G4: 4F039A | H4: NA | I4: 46234 | J4: BÚT | K4: 1 | L4: Ngày 03/01/2025 tại Kho Ngoại trú BHYT ghi nhận 1 cây bút không vặn chỉnh liều được | M4: NA | N4: Ngày 03/01/2025, nhận được hướng xử lý từ hãng Ngày 03/01/2025, Khách hàng hủy khiếu nại ("Sau khi khoa kiểm tra lại bút Toujeo, thì đó là bút của bệnh nhân đem từ nhà lên chứ không phải của Bệnh viện phát. Nên em xin thông tin lại cho công ty. Trường hợp này không cần phải giải quyết gi nữa ạ. Em cảm ơn chị đã hỗ trợ") --> Hoàn tất | R4: Xuất mẫu theo đợt | S4: 45728 | T4: =IF(I4="","CHƯA NHẬP NGÀY",TEXT(I4,"dd/mm/yyyy")) -> 31/07/2026 | U4: =IF(S4="","CHƯA NHẬP NGÀY",TEXT(S4,"dd/mm/yyyy")) -> 12/03/2025
A5: =ROW(B5)-3 -> 2 | B5: 45665 | C5: CC_020125-HCM | D5: BENH VIEN PHAM NGOC THACH | E5: 120 HONG BANG, PHUONG 12, QUAN 5, TP. HO CHI MINH | F5: BEPRASAN 20MG (H/VI/ 10V) | G5: NU6864 | H5: NA | I5: 46086 | J5: Hộp | K5: 1 | L5: NTBV báo phát hiện tình trạng lỗi khi đang cấp phát thuốc theo toa của bác sĩ, mở hộp thuốc thì thấy vỉ thuốc bị rách | M5: Lỗi từ nhà sản xuất | N5: Chấp nhận đổi hàng cho khách, hàng lỗi thu về chuyển sang khu vực chờ hủy theo xác nhận từ Phòng Kinh Doanh Dược --> Hoàn tất | P5: x | Q5: hình ảnh Zalo | R5: XUẤT MẪU NGAY | T5: =IF(I5="","CHƯA NHẬP NGÀY",TEXT(I5,"dd/mm/yyyy")) -> 05/03/2026 | U5: =IF(S5="","CHƯA NHẬP NGÀY",TEXT(S5,"dd/mm/yyyy")) -> CHƯA NHẬP NGÀY
A6: =ROW(B6)-3 -> 3 | B6: 45666 | C6: CC_030125-HCM | D6: TRUNG TAM Y TE QUAN 1 | E6: SO 2 DANG TAT, PHUONG TAN DINH, QUAN 1, TP.HCM | F6: DOLUTEGRAVIR, LAMIVUDINE AND TENOFOVIR DISOPROXIL FUMARATE TABLETS 50/300/300MG (HOP/1 LO 30 VIEN) | G6: E243664 | H6: 45533 | I6: 46262 | J6: Hộp | K6: 25 | L6: TTYT báo lỗi nắp thuốc bị ố vàng, trong đó có 2 lọ bị bung màng bọc lộ phần bông gòn với 1 lọ TTYT mở ra để kiểm tra chất lượng thuốc như hình đính kèm | M6: Lỗi từ nhà sản xuất | N6: Ngày 20/01/2025, nhận được thông tin, chấp nhận đổi hàng cho khách và hàng khiếu nại cho vào khu vực chờ xử lý, chờ quyết định của hãng | T6: =IF(I6="","CHƯA NHẬP NGÀY",TEXT(I6,"dd/mm/yyyy")) -> 28/08/2026 | U6: =IF(S6="","CHƯA NHẬP NGÀY",TEXT(S6,"dd/mm/yyyy")) -> CHƯA NHẬP NGÀY
A7: =ROW(B7)-3 -> 4 | B7: 45670 | C7: CC_040125-HCM | D7: BENH VIEN PHAP VIET | E7: 06 Nguyen Luong Bang Street, Phu My Hung, District 7, Ho Chi Minh City, Vietnam | F7: LOVENOX 40MG/0.4ML INJ. B/ 2 SYRINGES VN | G7: JS045A | H7: NA | I7: 46022 | J7: hộp | K7: 81 | L7: Ngày 12/12 BN mua 28 bơm về chích và cả 28 bơm đều bị rỉ như vậy Có thể BN nhận lô JS044A vì từ đầu tháng 10 đến 20/12/24, FV đang sử dụng lô này. BN ko nhớ rõ lô chỉ báo bị tương tự lô trước. · Ngày 9/1 BN mua tiếp 28 bơm lô JS045A ,BN chích tiếp 2 bơm đều bị rỉ, trả lại FV 26 bơm · Số lô JS045A, hạn dung: 31/12/2025, số hd: 212738 (27/12/24) · Số lượng còn lại: 81 hộp · BN người nước ngoài · FV đã đổi lại lô mới nhất cho BN JS371A, hạn dung: 30/6/2026. Đến thời điểm hiện tại không thấy BN phản ánh | M7: Lỗi từ nhà sản xuất | N7: Thu 10 hộp xuất sang văn phòng hãng, Khách yêu cầu thu luôn 81 hộp-> hãng đồng ý và tiến hành thu về Đã hoàn thành xuất mẫu sang hãng ngày 04/02/2025 Ngày 26/02/2025, nhận được kết quả điều tra của hãng và đã gửi email đến khách --> Hoàn tất | O7: x | T7: =IF(I7="","CHƯA NHẬP NGÀY",TEXT(I7,"dd/mm/yyyy")) -> 31/12/2025 | U7: =IF(S7="","CHƯA NHẬP NGÀY",TEXT(S7,"dd/mm/yyyy")) -> CHƯA NHẬP NGÀY
A8: =ROW(B8)-3 -> 5 | B8: 45670 | C8: CC_050125-ĐN HUY | D8: CONG TY CO PHAN Y KHOA BAC SY GIA DINH | E8: 73 NGUYEN HUU THO,PHUONG HOA THUAN TAY,QUAN HAI CHAU,THANH PHO DA NANG VIET NAM | F8: CALCIUM CORBIERE EXTRA 3SUPX10 10ML VN | G8: EVH2311 | H8: NA | I8: 08/04/2026 | J8: ống | K8: 1 | L8: Không có thông tin trên ống thuốc | M8: Lỗi từ nhà sản xuất | N8: Hãng chấp nhận đền bù, Xuất mẫu sang văn phòng hãng Ngày 17/01/2025, Khách hủy khiếu nại do không muốn cung cấp hồ sơ chứng từ cho việc hủy --> Hoàn tất | O8: x | T8: =IF(I8="","CHƯA NHẬP NGÀY",TEXT(I8,"dd/mm/yyyy")) -> 08/04/2026 | U8: =IF(S8="","CHƯA NHẬP NGÀY",TEXT(S8,"dd/mm/yyyy")) -> CHƯA NHẬP NGÀY
A9: =ROW(B9)-3 -> 6 | B9: 45671 | C9: CC_060125-HCM HUY | D9: BENH VIEN DA KHOA TINH TRA VINH | E9: SO 399, DUONG NGUYEN DANG, KHOM 10, PHUONG 7, THANH PHO TRA VINH, TINH TRA VINH | F9: TOUJEO SOLOSTAR 450IU B/5 PENS X 1.5ML | G9: 4F039A | H9: 45323 | I9: 46234 | J9: bút | K9: 2 | L9: 1 bút xoay thể tích không được, 1 bút xoay được nhưng bấm không ra thuốc | M9: Không xác định được nguyên nhân | N9: Ngày 14/01/2025, gửi email cho hãng Hãng nhận khiếu nại nhưng vẫn đang đợi thêm thông tin điều tra từ phía khách hàng Ngày 06/02/2025, khách hủy khiếu nại --> Hoàn tất | T9: =IF(I9="","CHƯA NHẬP NGÀY",TEXT(I9,"dd/mm/yyyy")) -> 31/07/2026 | U9: =IF(S9="","CHƯA NHẬP NGÀY",TEXT(S9,"dd/mm/yyyy")) -> CHƯA NHẬP NGÀY
A10: =ROW(B10)-3 -> 7 | B10: 45671 | C10: CC_070125-HCM | D10: BENH VIEN DA KHOA TINH BINH THUAN | E10: DUONG TRUONG CHINH, PHUONG PHU TAI, TP PHAN THIET, TINH BINH THUAN | F10: LANTUS SOLOSTAR 100IU/ML B/5 PENS X 3ML | G10: 4F9694A | H10: NA | I10: 46446 | J10: bút | K10: 1 | L10: BV báo bút tiêm cấp cho bệnh nhân sử dụng, vặn chỉnh liều được nhưng bấm rất cứng và không ra thuốc. | M10: Lỗi từ nhà sản xuất | N10: Ngày 15/01/2025, gửi email cho hãng Ngày 16/01/2025. nhận được thông tin từu khách, báo hãng và hãng đồng ý đền bù cho khách, hàng thu về xuất sang văn phòng hãng | O10: x | T10: =IF(I10="","CHƯA NHẬP NGÀY",TEXT(I10,"dd/mm/yyyy")) -> 28/02/2027 | U10: =IF(S10="","CHƯA NHẬP NGÀY",TEXT(S10,"dd/mm/yyyy")) -> CHƯA NHẬP NGÀY
A11: =ROW(B11)-3 -> 8 | B11: 45672 | C11: CC_080125-HCM | D11: BENH VIEN PHAP VIET | E11: 6 NGUYEN LUONG BANG, PHUONG TAN PHU,DO THI MOI NAM TP, QUAN 7, TP HCM | F11: LOVENOX 40MG/0.4ML INJ. B/ 2 SYRINGES VN | G11: JS044A | H11: NA | I11: NA | J11: NA | K11: NA | L11: Ngày 12/12 BN mua 28 bơm về chích và cả 28 bơm đều bị rỉ như vậy Có thể BN nhận lô JS044A vì từ đầu tháng 10 đến 20/12/24, FV đang sử dụng lô này. BN ko nhớ rõ lô chỉ báo bị tương tự lô trước. · Ngày 9/1 BN mua tiếp 28 bơm lô JS045A ,BN chích tiếp 2 bơm đều bị rỉ, trả lại FV 26 bơm · Số lô JS045A, hạn dung: 31/12/2025, số hd: 212738 (27/12/24) · Số lượng còn lại: 81 hộp · BN người nước ngoài · FV đã đổi lại lô mới nhất cho BN JS371A, hạn dung: 30/6/2026. Đến thời điểm hiện tại không thấy BN phản ánh | M11: Lỗi từ nhà sản xuất | N11: Tương tự case CC_040125-HCM -->Hoàn tất | T11: =IF(I11="","CHƯA NHẬP NGÀY",TEXT(I11,"dd/mm/yyyy")) -> NA | U11: =IF(S11="","CHƯA NHẬP NGÀY",TEXT(S11,"dd/mm/yyyy")) -> CHƯA NHẬP NGÀY
A12: =ROW(B12)-3 -> 9 | B12: 45677 | C12: CC_090125-HCM | D12: TRUNG TAM Y TE THANH PHO BIEN HOA | E12: 98/487 DUONG PHAM VAN THUAN, P. TAN MAI, TP. BIEN HOA, TINH DONG NAI | F12: DOLUTEGRAVIR, LAMIVUDINE AND TENOFOVIR DISOPROXIL FUMARATE TABLETS 50/300/300MG (HOP/1 LO 30 VIEN) | G12: E243694 | H12: 45535 | I12: 46264 | J12: Hộp | K12: 1 | L12: TTYT báo thuốc cấp cho bệnh nhận sử dụng thì bệnh nhân phát hiện báo viên thuốc màu xanh không phải màu cam như bình thường | M12: Không xác định được nguyên nhân | N12: Xin thêm thông tin từ khách, viên được phát hiện trong cấp lẻ cho bệnh nhân (BV giao cho bệnh nhân 1 hộp chẵn và 1 hộp lẻ) Đang đợi thông tin phản hồi của hãng Ngày 20/02/2025, hãng gửi công văn Ngày 21/02/2025, mail cho CS để thông tin đến khách --> Hoàn tất | T12: =IF(I12="","CHƯA NHẬP NGÀY",TEXT(I12,"dd/mm/yyyy")) -> 30/08/2026 | U12: =IF(S12="","CHƯA NHẬP NGÀY",TEXT(S12,"dd/mm/yyyy")) -> CHƯA NHẬP NGÀY
A13: =ROW(B13)-3 -> 10 | B13: 45681 | C13: CC_100125-HCM | D13: BENH VIEN PHAP VIET (CTTNHH YTE VIEN DONG VN) | E13: 6 NGUYEN LUONG BANG, PHUONG TAN PHU,DO THI MOI NAM TP, QUAN 7, TP HCM | F13: MIRGY 100MG CAPS 10'S | G13: 373C07 | H13: 45531 | I13: 46626 | J13: Hộp | K13: 1 | L13: Trong quá trình soạn thuốc cho bệnh nhân, phát hiện hộp Gabapentin (MIRGY) cap 100mg còn kín nguyên vẹn nhưng không có thuốc bên trong | M13: Lỗi từ nhà sản xuất | N13: Hãng chấp nhận đền bù, xuất mẫu sang văn phòng hãng Ngày 10/02/2024, nhập kho và xuất mẫu trả hãng --> Hoàn tất | O13: x | T13: =IF(I13="","CHƯA NHẬP NGÀY",TEXT(I13,"dd/mm/yyyy")) -> 27/08/2027 | U13: =IF(S13="","CHƯA NHẬP NGÀY",TEXT(S13,"dd/mm/yyyy")) -> CHƯA NHẬP NGÀY
A14: =ROW(B14)-3 -> 11 | B14: 45695 | C14: CC_110225-HCM HUY | D14: CONG TY CO PHAN BENH VIEN DAI HOC Y DUOC-HOANG ANH GIA LAI | E14: 238 LE DUAN, P.TRA BA,TP.PLEIKU,TINH GIA LAI | F14: VERORAB BOX OF 10 VIALS + 10 SYRINGES | G14: W1C561V | H14: 44872 | I14: 45961 | J14: Lọ | K14: 1 | L14: Khoa nhi nói pha nước vào vacxin verorab màu không trong hơi đục và dẻo. | M14: Lỗi từ nhà sản xuất | N14: 10/02/2025 báo email sang hãng, nhận được hướng xử lý từ hãng Ngày 13/02/2025, CS thông tin số lô --> Hoàn tất Ngày 06/03/2025, khách hủy khiếu nại, do không cung cấp được chứng từ cho việc đền bù | O14: x | T14: =IF(I14="","CHƯA NHẬP NGÀY",TEXT(I14,"dd/mm/yyyy")) -> 31/10/2025 | U14: =IF(S14="","CHƯA NHẬP NGÀY",TEXT(S14,"dd/mm/yyyy")) -> CHƯA NHẬP NGÀY
A15: =ROW(B15)-3 -> 12 | B15: 45698 | C15: CC_120225-HCM | D15: BENH VIEN THONG NHAT | E15: 1 LY THUONG KIET, PHUONG 7, QUAN TAN BINH, TP. HO CHI MINH | F15: TEGRUCIL-1 (HOP/100VIEN) - EU | G15: 243474 | H15: NA | I15: 46713 | J15: Viên | K15: 2790 | L15: Tháng 9/2024 Viện kiểm nghiệm thuốc TP.HCM có thực hiện lấy mẫu thuốc Tegrucil-1, số lô 241600. Đến tháng 02/2025 Bệnh viện Thống Nhất có nhận được kết quả mẫu thuốc không đạt yêu cầu chất lượng theo quy định (file đính kèm). Hiện nay, lô thuốc trên đã sử dụng hết và bệnh viện đang tồn 2.790 viên Tegrucil-1, số lô 243474. Yêu cầu công ty kiểm tra chất lượng và phản hồi lại bằng văn bản lô thuốc số 243474 để bệnh viện tiếp tục sử dụng | N15: Ngày 11/02/2025, gửi email đến hãng và hãng nhận thông tin, đang chờ fb từ hãng | T15: =IF(I15="","CHƯA NHẬP NGÀY",TEXT(I15,"dd/mm/yyyy")) -> 22/11/2027 | U15: =IF(S15="","CHƯA NHẬP NGÀY",TEXT(S15,"dd/mm/yyyy")) -> CHƯA NHẬP NGÀY
A16: =ROW(B16)-3 -> 13 | B16: 45699 | C16: CC_130225-HCM | D16: CONG TY CO PHAN BENH VIEN MY PHUOC | E16: THUA DAT SO 2292, TO BAN DO SO 58, DUONG TC3, TO 6, KHU PHO 3, PHUONG MY PHUOC, THANH PHO BEN CAT, TINH BINH DUONG, VIET NAM | F16: VAXIGRIP TETRA BOX OF 1 SYR 0.5ML | G16: Y4A171V | H16: 45471 | I16: 45808 | J16: Hộp | K16: 1 | L16: 1 hộp vaccine vaxigrip bị nghẹt pitton không đẩy lên được | M16: Lỗi từ nhà sản xuất | N16: 11/02/2025 báo email cho hãng và nhận được hướng xử lý 12/02/2025 nhận được thông tin số lô và hạn dùng sản phẩm khiếu nại --> Hoàn tất | O16: x | P16: x | Q16: zalo | T16: =IF(I16="","CHƯA NHẬP NGÀY",TEXT(I16,"dd/mm/yyyy")) -> 31/05/2025 | U16: =IF(S16="","CHƯA NHẬP NGÀY",TEXT(S16,"dd/mm/yyyy")) -> CHƯA NHẬP NGÀY
A17: =ROW(B17)-3 -> 14 | B17: 45701 | C17: CC_140225-HCM | D17: TRUNG TAM TIEM CHUNG VAC XIN NINH HOA | E17: 594 - 596 TRAN QUY CAP, TO DAN PHO 1, PHUONG NINH HIEP, THI XA NINH HOA, TINH KHANH HOA | F17: VERORAB 0.5ML 10D INJ VL10+P10 M36 H VN | G17: X1D421V | H17: 45274 | I17: 46356 | J17: hộp | K17: 1 | L17: 1 hộp vaccine Verorab không bơm nước pha vào lọ được và phần kim bị gỉ sét | M17: Lỗi từ nhà sản xuất | N17: 14/02/2025 báo email cho hãng 17/02/2025 hãng chấp nhận khiếu nại và tiến hành thu hồi xuất sang văn phòng hãng --> Hoàn tất | O17: x | P17: x | Q17: zalo | T17: =IF(I17="","CHƯA NHẬP NGÀY",TEXT(I17,"dd/mm/yyyy")) -> 30/11/2026 | U17: =IF(S17="","CHƯA NHẬP NGÀY",TEXT(S17,"dd/mm/yyyy")) -> CHƯA NHẬP NGÀY
A18: =ROW(B18)-3 -> 15 | B18: 45707 | C18: CC_150225-HCM | D18: Zuellig Viet Nam | E18: 7-9 Đường Số 8, Tân Tạo A, Bình Tân, Hồ Chí Minh | F18: IMOJEV 0.5ML 1DOSE | G18: 08A2306GA | H18: NA | I18: 46164 | J18: hộp | K18: 1 | L18: Trong đợt nhận hàng IMOJEV vừa qua từ Hoàng Đức, kho ZPV có phát hiện một trường hợp hàng bị hư hỏng (hộp bị móp) được ghi nhận như hình ảnh và biên bản đính kèm | M18: Lỗi từ nhà sản xuất | N18: 19/02/2025 báo email cho hãng 20/02/2025 nhận được phản hồi từ hãng. Không ảnh hưởng chất lượng nên hàng bán bình thường (móp nhẹ) | T18: =IF(I18="","CHƯA NHẬP NGÀY",TEXT(I18,"dd/mm/yyyy")) -> 22/05/2026 | U18: =IF(S18="","CHƯA NHẬP NGÀY",TEXT(S18,"dd/mm/yyyy")) -> CHƯA NHẬP NGÀY
A19: =ROW(B19)-3 -> 16 | B19: 45715 | C19: CC_160225-HCM | D19: CONG TY CO PHAN DUOC PHAM AN KHANG PHARMA | E19: LO 2.11H, DUONG SO 6, KHU CONG NGHIEP TRA NOC II, PHUONG PHUOC THOI, QUAN O MON, THANH PHO CAN THO | F19: OSPAMOX 500MG TAB 10'S | G19: 00523 | H19: NA | I19: 46618 | J19: Vỉ | K19: 9 | L19: Sản phẩm bị lỗi thiếu số lượng trong vỉ | M19: Lỗi từ nhà sản xuất | N19: 27/02/2025, nhận được xác nhận từ team kinh doanh đổi hàng cho khách 03/03/2025 báo email complaint với nhà sản xuất | T19: =IF(I19="","CHƯA NHẬP NGÀY",TEXT(I19,"dd/mm/yyyy")) -> 19/08/2027 | U19: =IF(S19="","CHƯA NHẬP NGÀY",TEXT(S19,"dd/mm/yyyy")) -> CHƯA NHẬP NGÀY
A20: =ROW(B20)-3 -> 17 | B20: 45728 | C20: CC_170325-HN | D20: BENH VIEN DA KHOA PHUONG DONG | E20: SO 9, PHO VIEN, PHUONG CO NHUE 2, QUAN BAC TU LIEM , HA NOI | F20: PODOXRED 500MG (H/1 LO) | G20: H240904 | H20: NA | I20: 46326 | J20: hộp | K20: 1 | L20: lọ thuốc bị thủng đáy và bột bị rơi ra ngoài (hình ảnh đính kèm) | M20: Lỗi từ nhà sản xuất | N20: Nhận được email từ CS rằng hãng đồng ý đền bù 12/03/2025 | T20: =IF(I20="","CHƯA NHẬP NGÀY",TEXT(I20,"dd/mm/yyyy")) -> 31/10/2026 | U20: =IF(S20="","CHƯA NHẬP NGÀY",TEXT(S20,"dd/mm/yyyy")) -> CHƯA NHẬP NGÀY
A21: =ROW(B21)-3 -> 18 | B21: 45729 | C21: CC_180325-HN | D21: CONG TY DUOC PHAM HA NOI | F21: Depakine 200mg TABEC TB40 – SPAIN | G21: ELB03419 4R983 | L21: Depakine Solution 200mg BTLX40ml VN tổng số lượng 2.000 hộp ở hóa đơn 23438 số lượng 1.000 hộp và hóa đơn 23463 số lượng 1.000 hộp cùng lô ELB03419 hạn dùng 04/2027 có 01 hộp bị móp méo trong kiện nguyên. Depakine 200mg TABEC TB40 – SPAIN hóa đơn 23464 số lượng 1.720 hộp lô 4R983 hạn dùng 05/2027 có 07 hộp bị móp méo trong kiện nguyên | T21: =IF(I21="","CHƯA NHẬP NGÀY",TEXT(I21,"dd/mm/yyyy")) -> CHƯA NHẬP NGÀY | U21: =IF(S21="","CHƯA NHẬP NGÀY",TEXT(S21,"dd/mm/yyyy")) -> CHƯA NHẬP NGÀY

Sheet 2025-New
F1: BIỂU MẪU 02/ FORM 02 DANH SÁCH KHIẾU NẠI KHÁCH HÀNG NĂM 2025 LIST OF CUSTOMER COMPLAINTS - YEAR 2025
A3: STT No. | B3: HÃNG | C3: Ngày date | D3: Code CC- | E3: Ticket | F3: Tên khách hàng Customer | G3: Địa chỉ address | H3: Tên sản phẩm Product name | I3: Số Lô batch No. | J3: NSX Mfg date | K3: HD Exp date | L3: Đơn vị tính Unit | M3: Số Lượng Quanity | N3: Lý do khiếu nại Reason of complaint | O3: Nguyên nhân khiếu nại/ Cause of complaint | P3: Tình trạng/ Status | Q3: BẢO MẬT THÔNG TIN CÁ NHÂN | R3: HÌNH THỨC NHẬN | S3: XÁC NHẬN TỪ HÃNG | T3: NGÀY NHẬN | U3: THÁNG | V3: FIXED EXP | W3: FIXED IMPORT | X3: FIXED Mft. | Y3: Link | Z3: Năm | AA3: CHI NHÁNH
A4: 1 | B4: SA | C4: 45660 | D4: CC_010125-HCM HUY | F4: CONG TY CO PHAN BENH VIEN DA KHOA HOAN MY DA LAT | G4: DOI LONG THO, P10, TP DA LAT, TINH LAM DONG | H4: TOUJEO SOLOSTAR 450IU B/5 PENS X 1.5ML | I4: 4F039A | J4: NA | K4: 46234 | L4: BÚT | M4: 1 | N4: Ngày 03/01/2025 tại Kho Ngoại trú BHYT ghi nhận 1 cây bút không vặn chỉnh liều được | O4: NA | P4: Ngày 03/01/2025, nhận được hướng xử lý từ hãng Ngày 03/01/2025, Khách hàng hủy khiếu nại ("Sau khi khoa kiểm tra lại bút Toujeo, thì đó là bút của bệnh nhân đem từ nhà lên chứ không phải của Bệnh viện phát. Nên em xin thông tin lại cho công ty. Trường hợp này không cần phải giải quyết gi nữa ạ. Em cảm ơn chị đã hỗ trợ") --> Hoàn tất | R4: =IF($S4="Chờ xử lý", TRUE, FALSE) -> FALSE | S4: Chờ hủy | V4: =IF(K4="","CHƯA NHẬP NGÀY",TEXT(K4,"dd/mm/yyyy")) -> 31/07/2026 | W4: =IF(T4="","CHƯA NHẬP NGÀY",TEXT(T4,"dd/mm/yyyy")) -> CHƯA NHẬP NGÀY | X4: =IF(J4="","CHƯA NHẬP NGÀY",TEXT(J4,"dd/mm/yyyy")) -> NA | Y4: =HYPERLINK('Danh mục'!$D$1&"20"&MID(D4,8,2)&"\"&D4,D4) -> CC_010125-HCM HUY | Z4: =YEAR(Table2[[#This Row],[Ngày date]]) -> 2025 | AA4: =IF(ISNUMBER(SEARCH("HCM",D4)),"HCM", IF(ISNUMBER(SEARCH("HN",D4)),"HN", IF(ISNUMBER(SEARCH("ĐN",D4)),"ĐN",""))) -> HCM
A5: =IF(Table2[[#This Row],[Code CC- ]]="", "", A4+1) -> 2 | B5: NV | C5: 45665 | D5: CC_020125-HCM | F5: BENH VIEN PHAM NGOC THACH | G5: 120 HONG BANG, PHUONG 12, QUAN 5, TP. HO CHI MINH | H5: BEPRASAN 20MG (H/VI/ 10V) | I5: NU6864 | J5: NA | K5: 46086 | L5: Hộp | M5: 1 | N5: NTBV báo phát hiện tình trạng lỗi khi đang cấp phát thuốc theo toa của bác sĩ, mở hộp thuốc thì thấy vỉ thuốc bị rách | O5: Lỗi từ nhà sản xuất | P5: Chấp nhận đổi hàng cho khách, hàng lỗi thu về chuyển sang khu vực chờ hủy theo xác nhận từ Phòng Kinh Doanh Dược --> Hoàn tất | Q5: x | R5: ZALO | S5: Trả lời câu hỏi | U5: =MONTH(Table2[[#This Row],[Ngày date]]) -> 1 | V5: =IF(K5="","CHƯA NHẬP NGÀY",TEXT(K5,"dd/mm/yyyy")) -> 05/03/2026 | W5: =IF(T5="","CHƯA NHẬP NGÀY",TEXT(T5,"dd/mm/yyyy")) -> CHƯA NHẬP NGÀY | X5: =IF(J5="","CHƯA NHẬP NGÀY",TEXT(J5,"dd/mm/yyyy")) -> NA | Y5: =HYPERLINK('Danh mục'!$D$1&"20"&MID(D5,8,2)&"\"&D5,D5) -> CC_020125-HCM | Z5: =YEAR(Table2[[#This Row],[Ngày date]]) -> 2025 | AA5: =IF(ISNUMBER(SEARCH("HCM",D5)),"HCM", IF(ISNUMBER(SEARCH("HN",D5)),"HN", IF(ISNUMBER(SEARCH("ĐN",D5)),"ĐN",""))) -> HCM
A6: =IF(Table2[[#This Row],[Code CC- ]]="", "", A5+1) -> 3 | B6: HT | C6: 45666 | D6: CC_030125-HCM | F6: TRUNG TAM Y TE QUAN 1 | G6: SO 2 DANG TAT, PHUONG TAN DINH, QUAN 1, TP.HCM | H6: DOLUTEGRAVIR, LAMIVUDINE AND TENOFOVIR DISOPROXIL FUMARATE TABLETS 50/300/300MG (HOP/1 LO 30 VIEN) | I6: E243664 | J6: 45533 | K6: 46262 | L6: Hộp | M6: 25 | N6: TTYT báo lỗi nắp thuốc bị ố vàng, trong đó có 2 lọ bị bung màng bọc lộ phần bông gòn với 1 lọ TTYT mở ra để kiểm tra chất lượng thuốc như hình đính kèm | O6: Lỗi từ nhà sản xuất | P6: Ngày 20/01/2025, nhận được thông tin, chấp nhận đổi hàng cho khách và hàng khiếu nại cho vào khu vực chờ xử lý, chờ quyết định của hãng --> Hoàn tất | S6: Chờ hủy | T6: 45736 | U6: =MONTH(Table2[[#This Row],[Ngày date]]) -> 1 | V6: =IF(K6="","CHƯA NHẬP NGÀY",TEXT(K6,"dd/mm/yyyy")) -> 28/08/2026 | W6: =IF(T6="","CHƯA NHẬP NGÀY",TEXT(T6,"dd/mm/yyyy")) -> 20/03/2025 | X6: =IF(J6="","CHƯA NHẬP NGÀY",TEXT(J6,"dd/mm/yyyy")) -> 29/08/2024 | Y6: =HYPERLINK('Danh mục'!$D$1&"20"&MID(D6,8,2)&"\"&D6,D6) -> CC_030125-HCM | Z6: =YEAR(Table2[[#This Row],[Ngày date]]) -> 2025 | AA6: =IF(ISNUMBER(SEARCH("HCM",D6)),"HCM", IF(ISNUMBER(SEARCH("HN",D6)),"HN", IF(ISNUMBER(SEARCH("ĐN",D6)),"ĐN",""))) -> HCM
A7: =IF(Table2[[#This Row],[Code CC- ]]="", "", A6+1) -> 4 | B7: SA | C7: 45670 | D7: CC_040125-HCM | F7: BENH VIEN PHAP VIET | G7: 06 Nguyen Luong Bang Street, Phu My Hung, District 7, Ho Chi Minh City, Vietnam | H7: LOVENOX 40MG/0.4ML INJ. B/ 2 SYRINGES VN | I7: JS045A | J7: NA | K7: 46022 | L7: hộp | M7: 81 | N7: Ngày 12/12 BN mua 28 bơm về chích và cả 28 bơm đều bị rỉ như vậy Có thể BN nhận lô JS044A vì từ đầu tháng 10 đến 20/12/24, FV đang sử dụng lô này. BN ko nhớ rõ lô chỉ báo bị tương tự lô trước. · Ngày 9/1 BN mua tiếp 28 bơm lô JS045A ,BN chích tiếp 2 bơm đều bị rỉ, trả lại FV 26 bơm · Số lô JS045A, hạn dung: 31/12/2025, số hd: 212738 (27/12/24) · Số lượng còn lại: 81 hộp · BN người nước ngoài · FV đã đổi lại lô mới nhất cho BN JS371A, hạn dung: 30/6/2026. Đến thời điểm hiện tại không thấy BN phản ánh | O7: Lỗi từ nhà sản xuất | P7: Thu 10 hộp xuất sang văn phòng hãng, Khách yêu cầu thu luôn 81 hộp-> hãng đồng ý và tiến hành thu về Đã hoàn thành xuất mẫu sang hãng ngày 04/02/2025 Ngày 26/02/2025, nhận được kết quả điều tra của hãng và đã gửi email đến khách --> Hoàn tất | S7: XUẤT MẪU NGAY NHẬN | U7: =MONTH(Table2[[#This Row],[Ngày date]]) -> 1 | V7: =IF(K7="","CHƯA NHẬP NGÀY",TEXT(K7,"dd/mm/yyyy")) -> 31/12/2025 | W7: =IF(T7="","CHƯA NHẬP NGÀY",TEXT(T7,"dd/mm/yyyy")) -> CHƯA NHẬP NGÀY | X7: =IF(J7="","CHƯA NHẬP NGÀY",TEXT(J7,"dd/mm/yyyy")) -> NA | Y7: =HYPERLINK('Danh mục'!$D$1&"20"&MID(D7,8,2)&"\"&D7,D7) -> CC_040125-HCM | Z7: =YEAR(Table2[[#This Row],[Ngày date]]) -> 2025 | AA7: =IF(ISNUMBER(SEARCH("HCM",D7)),"HCM", IF(ISNUMBER(SEARCH("HN",D7)),"HN", IF(ISNUMBER(SEARCH("ĐN",D7)),"ĐN",""))) -> HCM
A8: =IF(Table2[[#This Row],[Code CC- ]]="", "", A7+1) -> 5 | B8: OPELLA | C8: 45670 | D8: CC_050125-ĐN HUY | F8: CONG TY CO PHAN Y KHOA BAC SY GIA DINH | G8: 73 NGUYEN HUU THO,PHUONG HOA THUAN TAY,QUAN HAI CHAU,THANH PHO DA NANG VIET NAM | H8: CALCIUM CORBIERE EXTRA 3SUPX10 10ML VN | I8: EVH2311 | J8: NA | K8: 08/04/2026 | L8: ống | M8: 1 | N8: Không có thông tin trên ống thuốc | O8: Lỗi từ nhà sản xuất | P8: Hãng chấp nhận đền bù, Xuất mẫu sang văn phòng hãng Ngày 17/01/2025, Khách hủy khiếu nại do không muốn cung cấp hồ sơ chứng từ cho việc hủy --> Hoàn tất | S8: HỦY KHIẾU NẠI | U8: =MONTH(Table2[[#This Row],[Ngày date]]) -> 1 | V8: =IF(K8="","CHƯA NHẬP NGÀY",TEXT(K8,"dd/mm/yyyy")) -> 08/04/2026 | W8: =IF(T8="","CHƯA NHẬP NGÀY",TEXT(T8,"dd/mm/yyyy")) -> CHƯA NHẬP NGÀY | X8: =IF(J8="","CHƯA NHẬP NGÀY",TEXT(J8,"dd/mm/yyyy")) -> NA | Y8: =HYPERLINK('Danh mục'!$D$1&"20"&MID(D8,8,2)&"\"&D8,D8) -> CC_050125-ĐN HUY | Z8: =YEAR(Table2[[#This Row],[Ngày date]]) -> 2025 | AA8: =IF(ISNUMBER(SEARCH("HCM",D8)),"HCM", IF(ISNUMBER(SEARCH("HN",D8)),"HN", IF(ISNUMBER(SEARCH("ĐN",D8)),"ĐN",""))) -> ĐN
