Workbook

Sheet Sheet1
A1: item_code | B1: item_name | C1: supplier_code | D1: visa_no | E1: gross_weight | F1: net_weight | G1: cube | H1: tare_weight | I1: pallet_qty | J1: case_qty | K1: inner_pack | L1: is_active
A2: 3M118 | B2: 118 ATTEST BIOLOG INCUBATOR STEAM 56C | C2: 3M VIETNAM | E2: 1.241 | G2: =VLOOKUP(A2,[1]GỘP!$A:$M,13,0) -> 0.00036 | L2: TRUE
A3: 3M1522 | B3: 1522 BANG KEO 3.6 IN x 60 YD | C3: 3M VIETNAM | E3: 1.5 | G3: =VLOOKUP(A3,[1]GỘP!$A:$M,13,0) -> 0.002916 | L3: TRUE
A4: 3M2306 | B4: 2306 ONG NGHE LITTMANN XANH BIEN | C4: 3M VIETNAM | E4: 0.25 | G4: =VLOOKUP(A4,[1]GỘP!$A:$M,13,0) -> 0.001386 | L4: TRUE
A5: 3M290G | B5: 290G MAY 240 VAC DOC MAU TEST DO DO TIET TRUNG THIET BI Y TE (CASE/1CAI) | C5: 3M VIETNAM | E5: 4.328 | G5: =VLOOKUP(A5,[1]GỘP!$A:$M,13,0) -> 0.037758 | L5: TRUE
A6: 3M390 | B6: 390 MAY DOC HUYNH QUANG TEST VI SINH TIET TRUNG EO (CASE/1CAI) | C6: 3M VIETNAM | E6: 2.412 | G6: =VLOOKUP(A6,[1]GỘP!$A:$M,13,0) -> 0.02048 | L6: TRUE
A7: 3M63500 | B7: 63500 MEN U AM (5/CASE) | C7: 3M VIETNAM | E7: 0.289 | G7: =VLOOKUP(A7,[1]GỘP!$A:$M,13,0) -> 0.004 | L7: TRUE
A8: 3MN95-23252 | B8: GOWN (AO CHOANG CHO PHAU THUAT) [TUI/10CAI] | C8: 3M VIETNAM | E8: 0.089 | G8: =VLOOKUP(A8,[1]GỘP!$A:$M,13,0) -> 0.000406 | L8: TRUE
A9: AB1100026 | B9: TANATRIL TAB 10MG 100'S | C9: ABBOTT | D9: VN-22051-19 | E9: 0.034 | G9: =VLOOKUP(A9,[1]GỘP!$A:$M,13,0) -> 0.000123 | J9: 160 | L9: TRUE
A10: AB6100013 | B10: HEPTRAL 400 (H/30V) | C10: ABBOTT | D10: 3931/2020/ĐKSP | E10: 0.058 | G10: =VLOOKUP(A10,[1]GỘP!$A:$M,13,0) -> 0.00033792 | J10: 24 | L10: TRUE
A11: ST9-ACP2-007-022 | B11: AMPLATZER AMULET LAA OCCLUDER 22MM | C11: ABBOTT | D11: 2400072DKLH/BYT-HTTB | E11: 0.362 | G11: =VLOOKUP(A11,[1]GỘP!$A:$M,13,0) -> 0.003498 | L11: TRUE
A12: ST9-ACP2-010-025 | B12: AMPLATZER AMULET LAA OCCLUDER 25MM | C12: ABBOTT | D12: 2400072DKLH/BYT-HTTB | E12: 0.364 | G12: =VLOOKUP(A12,[1]GỘP!$A:$M,13,0) -> 0.003498 | L12: TRUE
A13: ST9-ACP2-010-028 | B13: AMPLATZER AMULET LAA OCCLUDER 28MM | C13: ABBOTT | D13: 2400072DKLH/BYT-HTTB | E13: 0.364 | G13: =VLOOKUP(A13,[1]GỘP!$A:$M,13,0) -> 0.00352176 | L13: TRUE
A14: ST9-ASD-010 | B14: AMPLATZER SEPTAL OCCLUDER 10MM | C14: ABBOTT | D14: 14580NK/BYT-TB-CT | E14: 0.106 | G14: =VLOOKUP(A14,[1]GỘP!$A:$M,13,0) -> 0.00140175 | L14: TRUE
A15: ST9-ASD-012 | B15: AMPLATZER SEPTAL OCCLUDER 12MM | C15: ABBOTT | D15: 14580NK/BYT-TB-CT | E15: 0.106 | G15: =VLOOKUP(A15,[1]GỘP!$A:$M,13,0) -> 0.00140175 | L15: TRUE
A16: ST9-ASD-014 | B16: AMPLATZER SEPTAL OCCLUDER 14MM | C16: ABBOTT | D16: 14580NK/BYT-TB-CT | E16: 0.106 | G16: =VLOOKUP(A16,[1]GỘP!$A:$M,13,0) -> 0.00140175 | L16: TRUE
A17: ST9-ASD-016 | B17: AMPLATZER SEPTAL OCCLUDER 16MM | C17: ABBOTT | D17: 14580NK/BYT-TB-CT | E17: 0.106 | G17: =VLOOKUP(A17,[1]GỘP!$A:$M,13,0) -> 0.00140175 | L17: TRUE
A18: ST9-ASD-018 | B18: AMPLATZER SEPTAL OCCLUDER 18MM | C18: ABBOTT | D18: 14580NK/BYT-TB-CT | E18: 0.106 | G18: =VLOOKUP(A18,[1]GỘP!$A:$M,13,0) -> 0.00140175 | L18: TRUE
A19: ST9-ASD-020 | B19: AMPLATZER SEPTAL OCCLUDER 20MM | C19: ABBOTT | D19: 14580NK/BYT-TB-CT | E19: 0.106 | G19: =VLOOKUP(A19,[1]GỘP!$A:$M,13,0) -> 0.00140175 | L19: TRUE
A20: ST9-ASD-022 | B20: AMPLATZER SEPTAL OCCLUDER 22MM | C20: ABBOTT | D20: 14580NK/BYT-TB-CT | E20: 0.106 | G20: =VLOOKUP(A20,[1]GỘP!$A:$M,13,0) -> 0.00140175 | L20: TRUE
A21: ST9-ASD-024 | B21: AMPLATZER SEPTAL OCCLUDER 24MM | C21: ABBOTT | D21: 14580NK/BYT-TB-CT | E21: 0.106 | G21: =VLOOKUP(A21,[1]GỘP!$A:$M,13,0) -> 0.00140175 | L21: TRUE
A22: ST9-ASD-026 | B22: AMPLATZER SEPTAL OCCLUDER 26MM | C22: ABBOTT | D22: 14580NK/BYT-TB-CT | E22: 0.106 | G22: =VLOOKUP(A22,[1]GỘP!$A:$M,13,0) -> 0.00140175 | L22: TRUE
... A65: ST9-PDAP-03-02-L | B65: AMPLATZER PICCOLO OCCLUDER 3MM X 2MM | C65: ABBOTT | D65: 14355NK/BYT-TB-CT | E65: 0.176 | G65: =VLOOKUP(A65,[1]GỘP!$A:$M,13,0) -> 0.001758906 | L65: TRUE
A66: ST9-PDAP-03-04-L | B66: AMPLATZER PICCOLO OCCLUDER 3MM X 4MM | C66: ABBOTT | D66: 14355NK/BYT-TB-CT | E66: 0.176 | L66: TRUE
A67: ST9-PDAP-04-02-L | B67: AMPLATZER PICCOLO OCCLUDER 4MM X 2MM | C67: ABBOTT | D67: 14355NK/BYT-TB-CT | E67: 0.176 | G67: =VLOOKUP(A67,[1]GỘP!$A:$M,13,0) -> 0.001758906 | L67: TRUE
A68: ST9-PDAP-04-04-L | B68: AMPLATZER PICCOLO OCCLUDER 4MM X 4MM | C68: ABBOTT | D68: 14355NK/BYT-TB-CT | E68: 0.176 | G68: =VLOOKUP(A68,[1]GỘP!$A:$M,13,0) -> 0.001758906 | L68: TRUE
A69: ST9-PDAP-04-06-L | B69: AMPLATZER PICCOLO OCCLUDER 4MM X 6MM | C69: ABBOTT | D69: 14355NK/BYT-TB-CT | E69: 0.176 | G69: =VLOOKUP(A69,[1]GỘP!$A:$M,13,0) -> 0.00165834 | L69: TRUE
A70: ST9-PDAP-05-02-L | B70: AMPLATZER PICCOLO OCCLUDER 5MM X 2MM | C70: ABBOTT | D70: 14355NK/BYT-TB-CT | E70: 0.176 | G70: =VLOOKUP(A70,[1]GỘP!$A:$M,13,0) -> 0.001758906 | L70: TRUE
A71: ST9-PDAP-05-04-L | B71: AMPLATZER PICCOLO OCCLUDER 5MM X 4MM | C71: ABBOTT | D71: 14355NK/BYT-TB-CT | E71: 0.176 | G71: =VLOOKUP(A71,[1]GỘP!$A:$M,13,0) -> 0.001758906 | L71: TRUE
A72: ST9-PDAP-05-06-L | B72: AMPLATZER PICCOLO OCCLUDER 5MM X 6MM | C72: ABBOTT | D72: 14355NK/BYT-TB-CT | E72: 0.178 | G72: =VLOOKUP(A72,[1]GỘP!$A:$M,13,0) -> 0.00185148 | L72: TRUE
A73: ST9-PFO-018 | B73: AMPLATZER PFO OCCLUDER 18MM | C73: ABBOTT | D73: 14580NK/BYT-TB-CT | E73: 0.296 | G73: =VLOOKUP(A73,[1]GỘP!$A:$M,13,0) -> 0.0014175 | L73: TRUE
A74: ST9-PFO-025 | B74: PFO IMPLANT 25MM | C74: ABBOTT | D74: 14580NK/BYT-TB-CT | E74: 0.296 | G74: =VLOOKUP(A74,[1]GỘP!$A:$M,13,0) -> 0.0014175 | L74: TRUE
A75: ST9-PFO-035 | B75: PFO IMPLANT 35MM | C75: ABBOTT | D75: 14580NK/BYT-TB-CT | E75: 0.296 | G75: =VLOOKUP(A75,[1]GỘP!$A:$M,13,0) -> 0.0014175 | L75: TRUE
A76: ST9-PFO-1818 | B76: 9-PFO-1818 AMPLATZER TALISMAN PFO OCCLUDER | C76: ABBOTT | E76: 0.786 | G76: =VLOOKUP(A76,[1]GỘP!$A:$M,13,0) -> 0.0065723 | L76: TRUE
A77: ST9-PFO-2518 | B77: 9-PFO-2518 AMPLATZER TALISMAN PFO OCCLUDER | C77: ABBOTT | E77: 0.786 | G77: =VLOOKUP(A77,[1]GỘP!$A:$M,13,0) -> 0.0065723 | L77: TRUE
A78: ST9-PLUG-014 | B78: VASCULAR PLUG 14MM | C78: ABBOTT | D78: 14580NK/BYT-TB-CT | E78: 0.282 | G78: =VLOOKUP(A78,[1]GỘP!$A:$M,13,0) -> 0.000899 | L78: TRUE
A79: ST9-PLUG-016 | B79: VASCULAR PLUG 16MM | C79: ABBOTT | D79: 14580NK/BYT-TB-CT | E79: 0.282 | G79: =VLOOKUP(A79,[1]GỘP!$A:$M,13,0) -> 0.000899 | L79: TRUE
A80: ST9-SB-018 | B80: AMPLATZER SB II 18MM | C80: ABBOTT | D80: 14580NK/BYT-TB-CT | E80: 0.39 | G80: =VLOOKUP(A80,[1]GỘP!$A:$M,13,0) -> 0.00360144 | L80: TRUE
A81: ST9-SB-024 | B81: AMPLATZER SB II 24MM | C81: ABBOTT | D81: 14580NK/BYT-TB-CT | E81: 0.38 | G81: =VLOOKUP(A81,[1]GỘP!$A:$M,13,0) -> 0.003797625 | L81: TRUE
A82: ST9-SB-034 | B82: AMPLATZER SB II 34MM | C82: ABBOTT | D82: 14580NK/BYT-TB-CT | E82: 0.394 | G82: =VLOOKUP(A82,[1]GỘP!$A:$M,13,0) -> 0.003797625 | L82: TRUE
...
